


Error occured with last batch = 1Number of data per training batch = 10
Traceback (most recent call last):
  File "c:\Users\Rilwa\GoogleDrive\Warwick\PhD\ATI\BNN\layers_and_distributions.py", line 703, in train_loop
    preds = model( feature, tape=tape ) #TODO Debug, remove tape variable from model later
  File "C:\Users\Rilwa\Anaconda3\lib\site-packages\tensorflow_core\python\keras\engine\base_layer.py", line 822, in __call__
    outputs = self.call(cast_inputs, *args, **kwargs)
  File "c:\Users\Rilwa\GoogleDrive\Warwick\PhD\ATI\BNN\layers_and_distributions.py", line 52, in call
    x = self.SRCNN_1(inputs, tape=tape)
  File "C:\Users\Rilwa\Anaconda3\lib\site-packages\tensorflow_core\python\keras\engine\base_layer.py", line 822, in __call__
    outputs = self.call(cast_inputs, *args, **kwargs)
  File "c:\Users\Rilwa\GoogleDrive\Warwick\PhD\ATI\BNN\layers_and_distributions.py", line 121, in call
    self.prior_cross_entropy()
  File "c:\Users\Rilwa\GoogleDrive\Warwick\PhD\ATI\BNN\layers_and_distributions.py", line 235, in prior_cross_entropy
    ll_k = tf.reduce_sum( self.conv3_logkappa_prior_dist.log_prob(self.conv3_logkappa) )
AttributeError: 'SRCNN' object has no attribute 'conv3_logkappa_prior_dist'



Error occured with last batch = 4Number of data per training batch = 10
Traceback (most recent call last):
  File "c:\Users\Rilwa\GoogleDrive\Warwick\PhD\ATI\BNN\layers_and_distributions.py", line 703, in train_loop
    #TODO(akanni-ade): remove (mask) eror for predictions that are water i.e. null
  File "C:\Users\Rilwa\Anaconda3\lib\site-packages\tensorflow_core\python\keras\engine\base_layer.py", line 822, in __call__
    outputs = self.call(cast_inputs, *args, **kwargs)
  File "c:\Users\Rilwa\GoogleDrive\Warwick\PhD\ATI\BNN\layers_and_distributions.py", line 52, in call
    x = self.SRCNN_1(inputs, tape=tape)
  File "C:\Users\Rilwa\Anaconda3\lib\site-packages\tensorflow_core\python\keras\engine\base_layer.py", line 822, in __call__
    outputs = self.call(cast_inputs, *args, **kwargs)
  File "c:\Users\Rilwa\GoogleDrive\Warwick\PhD\ATI\BNN\layers_and_distributions.py", line 121, in call
    self.prior_cross_entropy()
  File "c:\Users\Rilwa\GoogleDrive\Warwick\PhD\ATI\BNN\layers_and_distributions.py", line 235, in prior_cross_entropy
    # Layer-wise variance scaling nus
AttributeError: 'SRCNN' object has no attribute 'conv3_logkappa_prior_dist'



Error occured with last batch = 7Number of data per training batch = 10
Traceback (most recent call last):
  File "c:\Users\Rilwa\GoogleDrive\Warwick\PhD\ATI\BNN\layers_and_distributions.py", line 703, in train_loop
  File "C:\Users\Rilwa\Anaconda3\lib\site-packages\tensorflow_core\python\keras\engine\base_layer.py", line 822, in __call__
    outputs = self.call(cast_inputs, *args, **kwargs)
  File "c:\Users\Rilwa\GoogleDrive\Warwick\PhD\ATI\BNN\layers_and_distributions.py", line 52, in call
    x = self.SRCNN_1(inputs, tape=tape)
  File "C:\Users\Rilwa\Anaconda3\lib\site-packages\tensorflow_core\python\keras\engine\base_layer.py", line 822, in __call__
    outputs = self.call(cast_inputs, *args, **kwargs)
  File "c:\Users\Rilwa\GoogleDrive\Warwick\PhD\ATI\BNN\layers_and_distributions.py", line 121, in call
    self.prior_cross_entropy()
  File "c:\Users\Rilwa\GoogleDrive\Warwick\PhD\ATI\BNN\layers_and_distributions.py", line 235, in prior_cross_entropy
    # Layer-wise variance scaling nus
AttributeError: 'SRCNN' object has no attribute 'conv3_logkappa_prior_dist'



Error occured with last batch = 1Number of data per training batch = 10
Traceback (most recent call last):
  File "c:\Users\Rilwa\GoogleDrive\Warwick\PhD\ATI\BNN\layers_and_distributions.py", line 705, in train_loop
    preds = model( feature, tape=tape ) #TODO Debug, remove tape variable from model later
  File "C:\Users\Rilwa\Anaconda3\lib\site-packages\tensorflow_core\python\keras\engine\base_layer.py", line 822, in __call__
    outputs = self.call(cast_inputs, *args, **kwargs)
  File "c:\Users\Rilwa\GoogleDrive\Warwick\PhD\ATI\BNN\layers_and_distributions.py", line 52, in call
    x = self.SRCNN_1(inputs, tape=tape)
  File "C:\Users\Rilwa\Anaconda3\lib\site-packages\tensorflow_core\python\keras\engine\base_layer.py", line 822, in __call__
    outputs = self.call(cast_inputs, *args, **kwargs)
  File "c:\Users\Rilwa\GoogleDrive\Warwick\PhD\ATI\BNN\layers_and_distributions.py", line 121, in call
    self.prior_cross_entropy()
  File "c:\Users\Rilwa\GoogleDrive\Warwick\PhD\ATI\BNN\layers_and_distributions.py", line 236, in prior_cross_entropy
    ll_conv1_nu = tf.reduce_sum( self.conv1_nu_dist.log_prob(self.conv1_nu) )
AttributeError: 'SRCNN' object has no attribute 'conv1_nu_dist'



Error occured with last batch = 1Number of data per training batch = 10
Traceback (most recent call last):
  File "c:\Users\Rilwa\GoogleDrive\Warwick\PhD\ATI\BNN\layers_and_distributions.py", line 705, in train_loop
    preds = model( feature, tape=tape ) #TODO Debug, remove tape variable from model later
  File "C:\Users\Rilwa\Anaconda3\lib\site-packages\tensorflow_core\python\keras\engine\base_layer.py", line 822, in __call__
    outputs = self.call(cast_inputs, *args, **kwargs)
  File "c:\Users\Rilwa\GoogleDrive\Warwick\PhD\ATI\BNN\layers_and_distributions.py", line 52, in call
    x = self.SRCNN_1(inputs, tape=tape)
  File "C:\Users\Rilwa\Anaconda3\lib\site-packages\tensorflow_core\python\keras\engine\base_layer.py", line 822, in __call__
    outputs = self.call(cast_inputs, *args, **kwargs)
  File "c:\Users\Rilwa\GoogleDrive\Warwick\PhD\ATI\BNN\layers_and_distributions.py", line 121, in call
    self.prior_cross_entropy()
  File "c:\Users\Rilwa\GoogleDrive\Warwick\PhD\ATI\BNN\layers_and_distributions.py", line 236, in prior_cross_entropy
    ll_conv1_nu = tf.reduce_sum( self.conv1_nu_dist.log_prob(self.conv1_nu) )
AttributeError: 'SRCNN' object has no attribute 'conv1_nu_dist'



Error occured with last batch = 4Number of data per training batch = 10
Traceback (most recent call last):
  File "c:\Users\Rilwa\GoogleDrive\Warwick\PhD\ATI\BNN\layers_and_distributions.py", line 705, in train_loop
    preds = model( feature, tape=tape ) #TODO Debug, remove tape variable from model later
  File "C:\Users\Rilwa\Anaconda3\lib\site-packages\tensorflow_core\python\keras\engine\base_layer.py", line 822, in __call__
    outputs = self.call(cast_inputs, *args, **kwargs)
  File "c:\Users\Rilwa\GoogleDrive\Warwick\PhD\ATI\BNN\layers_and_distributions.py", line 52, in call
    x = self.SRCNN_1(inputs, tape=tape)
  File "C:\Users\Rilwa\Anaconda3\lib\site-packages\tensorflow_core\python\keras\engine\base_layer.py", line 822, in __call__
    outputs = self.call(cast_inputs, *args, **kwargs)
  File "c:\Users\Rilwa\GoogleDrive\Warwick\PhD\ATI\BNN\layers_and_distributions.py", line 121, in call
    self.prior_cross_entropy()
  File "c:\Users\Rilwa\GoogleDrive\Warwick\PhD\ATI\BNN\layers_and_distributions.py", line 236, in prior_cross_entropy
    ll_conv1_nu = tf.reduce_sum( self.conv1_nu_prior_dist.log_prob( self.conv1_nu ) )
AttributeError: 'SRCNN' object has no attribute 'conv1_nu_dist'



Error occured with last batch = 1Number of data per training batch = 10
Traceback (most recent call last):
  File "c:\Users\Rilwa\GoogleDrive\Warwick\PhD\ATI\BNN\layers_and_distributions.py", line 705, in train_loop
    preds = model( feature, tape=tape ) #TODO Debug, remove tape variable from model later
  File "C:\Users\Rilwa\Anaconda3\lib\site-packages\tensorflow_core\python\keras\engine\base_layer.py", line 822, in __call__
    outputs = self.call(cast_inputs, *args, **kwargs)
  File "c:\Users\Rilwa\GoogleDrive\Warwick\PhD\ATI\BNN\layers_and_distributions.py", line 52, in call
    x = self.SRCNN_1(inputs, tape=tape)
  File "C:\Users\Rilwa\Anaconda3\lib\site-packages\tensorflow_core\python\keras\engine\base_layer.py", line 822, in __call__
    outputs = self.call(cast_inputs, *args, **kwargs)
  File "c:\Users\Rilwa\GoogleDrive\Warwick\PhD\ATI\BNN\layers_and_distributions.py", line 121, in call
    self.prior_cross_entropy()
  File "c:\Users\Rilwa\GoogleDrive\Warwick\PhD\ATI\BNN\layers_and_distributions.py", line 241, in prior_cross_entropy
    ll_conv1_tau = tf.reduce_sum( self.conv1_tau_dist.log_prob( tf.reshape(self.conv1_taus,[-1]) ) )
AttributeError: 'SRCNN' object has no attribute 'conv1_tau_dist'



Error occured with last batch = 1Number of data per training batch = 10
Traceback (most recent call last):
  File "c:\Users\Rilwa\GoogleDrive\Warwick\PhD\ATI\BNN\layers_and_distributions.py", line 705, in train_loop
    preds = model( feature, tape=tape ) #TODO Debug, remove tape variable from model later
  File "C:\Users\Rilwa\Anaconda3\lib\site-packages\tensorflow_core\python\keras\engine\base_layer.py", line 822, in __call__
    outputs = self.call(cast_inputs, *args, **kwargs)
  File "c:\Users\Rilwa\GoogleDrive\Warwick\PhD\ATI\BNN\layers_and_distributions.py", line 52, in call
    x = self.SRCNN_1(inputs, tape=tape)
  File "C:\Users\Rilwa\Anaconda3\lib\site-packages\tensorflow_core\python\keras\engine\base_layer.py", line 822, in __call__
    outputs = self.call(cast_inputs, *args, **kwargs)
  File "c:\Users\Rilwa\GoogleDrive\Warwick\PhD\ATI\BNN\layers_and_distributions.py", line 121, in call
    self.prior_cross_entropy()
  File "c:\Users\Rilwa\GoogleDrive\Warwick\PhD\ATI\BNN\layers_and_distributions.py", line 242, in prior_cross_entropy
    ll_conv2_tau = tf.reduce_sum( self.conv2_tau_prior_dist.log_prob( tf.reshape(self.conv2_taus,[-1]) ) )
AttributeError: 'SRCNN' object has no attribute 'conv2_taus'



Error occured with last batch = 1Number of data per training batch = 10
Traceback (most recent call last):
  File "c:\Users\Rilwa\GoogleDrive\Warwick\PhD\ATI\BNN\layers_and_distributions.py", line 705, in train_loop
    preds = model( feature, tape=tape ) #TODO Debug, remove tape variable from model later
  File "C:\Users\Rilwa\Anaconda3\lib\site-packages\tensorflow_core\python\keras\engine\base_layer.py", line 822, in __call__
    outputs = self.call(cast_inputs, *args, **kwargs)
  File "c:\Users\Rilwa\GoogleDrive\Warwick\PhD\ATI\BNN\layers_and_distributions.py", line 52, in call
    x = self.SRCNN_1(inputs, tape=tape)
  File "C:\Users\Rilwa\Anaconda3\lib\site-packages\tensorflow_core\python\keras\engine\base_layer.py", line 822, in __call__
    outputs = self.call(cast_inputs, *args, **kwargs)
  File "c:\Users\Rilwa\GoogleDrive\Warwick\PhD\ATI\BNN\layers_and_distributions.py", line 121, in call
    self.prior_cross_entropy()
  File "c:\Users\Rilwa\GoogleDrive\Warwick\PhD\ATI\BNN\layers_and_distributions.py", line 242, in prior_cross_entropy
    ll_conv2_tau = tf.reduce_sum( self.conv2_tau_prior_dist.log_prob( tf.reshape(self.conv2_taus,[-1]) ) )
AttributeError: 'SRCNN' object has no attribute 'conv2_taus'



Error occured with last batch = 4Number of data per training batch = 10
Traceback (most recent call last):
  File "c:\Users\Rilwa\GoogleDrive\Warwick\PhD\ATI\BNN\layers_and_distributions.py", line 705, in train_loop
    preds = model( feature, tape=tape ) #TODO Debug, remove tape variable from model later
  File "C:\Users\Rilwa\Anaconda3\lib\site-packages\tensorflow_core\python\keras\engine\base_layer.py", line 822, in __call__
    outputs = self.call(cast_inputs, *args, **kwargs)
  File "c:\Users\Rilwa\GoogleDrive\Warwick\PhD\ATI\BNN\layers_and_distributions.py", line 52, in call
    x = self.SRCNN_1(inputs, tape=tape)
  File "C:\Users\Rilwa\Anaconda3\lib\site-packages\tensorflow_core\python\keras\engine\base_layer.py", line 822, in __call__
    outputs = self.call(cast_inputs, *args, **kwargs)
  File "c:\Users\Rilwa\GoogleDrive\Warwick\PhD\ATI\BNN\layers_and_distributions.py", line 121, in call
    self.prior_cross_entropy()
  File "c:\Users\Rilwa\GoogleDrive\Warwick\PhD\ATI\BNN\layers_and_distributions.py", line 242, in prior_cross_entropy
    ll_conv2_tau = tf.reduce_sum( self.conv2_tau_prior_dist.log_prob( tf.reshape(self.conv2_taus,[-1]) ) )
AttributeError: 'SRCNN' object has no attribute 'conv2_taus'



Error occured with last batch = 1Number of data per training batch = 10
Traceback (most recent call last):
  File "c:\Users\Rilwa\GoogleDrive\Warwick\PhD\ATI\BNN\layers_and_distributions.py", line 705, in train_loop
    preds = model( feature, tape=tape ) #TODO Debug, remove tape variable from model later
  File "C:\Users\Rilwa\Anaconda3\lib\site-packages\tensorflow_core\python\keras\engine\base_layer.py", line 822, in __call__
    outputs = self.call(cast_inputs, *args, **kwargs)
  File "c:\Users\Rilwa\GoogleDrive\Warwick\PhD\ATI\BNN\layers_and_distributions.py", line 52, in call
    x = self.SRCNN_1(inputs, tape=tape)
  File "C:\Users\Rilwa\Anaconda3\lib\site-packages\tensorflow_core\python\keras\engine\base_layer.py", line 822, in __call__
    outputs = self.call(cast_inputs, *args, **kwargs)
  File "c:\Users\Rilwa\GoogleDrive\Warwick\PhD\ATI\BNN\layers_and_distributions.py", line 122, in call
    self.posterior_entropy() #TODO check that layer losses are sent to model losses
  File "c:\Users\Rilwa\GoogleDrive\Warwick\PhD\ATI\BNN\layers_and_distributions.py", line 261, in posterior_entropy
    ll_conv1_beta_logtau = tf.reduce_sum(self.conv1_beta_logtau_post_dist.log_prob( self.conv1_beta_logtau )) #This needs to be made as in the other one
AttributeError: 'SRCNN' object has no attribute 'conv1_beta_logtau_post_dist'



Error occured with last batch = 1Number of data per training batch = 10
Traceback (most recent call last):
  File "c:\Users\Rilwa\GoogleDrive\Warwick\PhD\ATI\BNN\layers_and_distributions.py", line 659, in train_loop
    preds = model( feature, tape=tape ) #TODO Debug, remove tape variable from model later
  File "C:\Users\Rilwa\Anaconda3\lib\site-packages\tensorflow_core\python\keras\engine\base_layer.py", line 822, in __call__
    outputs = self.call(cast_inputs, *args, **kwargs)
  File "c:\Users\Rilwa\GoogleDrive\Warwick\PhD\ATI\BNN\layers_and_distributions.py", line 52, in call
    x = self.SRCNN_1(inputs, tape=tape)
  File "C:\Users\Rilwa\Anaconda3\lib\site-packages\tensorflow_core\python\keras\engine\base_layer.py", line 822, in __call__
    outputs = self.call(cast_inputs, *args, **kwargs)
  File "c:\Users\Rilwa\GoogleDrive\Warwick\PhD\ATI\BNN\layers_and_distributions.py", line 122, in call
    self.posterior_entropy() #TODO check that layer losses are sent to model losses
  File "c:\Users\Rilwa\GoogleDrive\Warwick\PhD\ATI\BNN\layers_and_distributions.py", line 266, in posterior_entropy
    ll_conv3_weights = tf.reduce_sum( self.conv3_weights_dist.log_prob( self.conv3_weights ) )
  File "C:\Users\Rilwa\Anaconda3\lib\site-packages\tensorflow_probability\python\distributions\distribution.py", line 876, in log_prob
    return self._call_log_prob(value, name, **kwargs)
  File "C:\Users\Rilwa\Anaconda3\lib\site-packages\tensorflow_probability\python\distributions\distribution.py", line 856, in _call_log_prob
    value, name='value', dtype_hint=self.dtype)
  File "C:\Users\Rilwa\Anaconda3\lib\site-packages\tensorflow_probability\python\distributions\distribution.py", line 175, in _convert_to_tensor
    value, dtype=dtype, dtype_hint=dtype_hint, name=name)
  File "C:\Users\Rilwa\Anaconda3\lib\site-packages\tensorflow_core\python\framework\ops.py", line 1256, in convert_to_tensor_v2
    as_ref=False)
  File "C:\Users\Rilwa\Anaconda3\lib\site-packages\tensorflow_core\python\framework\ops.py", line 1314, in convert_to_tensor
    ret = conversion_func(value, dtype=dtype, name=name, as_ref=as_ref)
  File "C:\Users\Rilwa\Anaconda3\lib\site-packages\tensorflow_core\python\framework\constant_op.py", line 317, in _constant_tensor_conversion_function
    return constant(v, dtype=dtype, name=name)
  File "C:\Users\Rilwa\Anaconda3\lib\site-packages\tensorflow_core\python\framework\constant_op.py", line 258, in constant
    allow_broadcast=True)
  File "C:\Users\Rilwa\Anaconda3\lib\site-packages\tensorflow_core\python\framework\constant_op.py", line 266, in _constant_impl
    t = convert_to_eager_tensor(value, ctx, dtype)
  File "C:\Users\Rilwa\Anaconda3\lib\site-packages\tensorflow_core\python\framework\constant_op.py", line 96, in convert_to_eager_tensor
    return ops.EagerTensor(value, ctx.device_name, dtype)
ValueError: Attempt to convert a value (<tensorflow_probability.python.layers.conv_variational.Conv2DReparameterization object at 0x000001961F6A1A90>) with an unsupported type (<class 'tensorflow_probability.python.layers.conv_variational.Conv2DReparameterization'>) to a Tensor.



Error occured with last batch = 1Number of data per training batch = 10
Traceback (most recent call last):
  File "c:\Users\Rilwa\GoogleDrive\Warwick\PhD\ATI\BNN\layers_and_distributions.py", line 677, in train_loop
    kl_loss = tf.math.reduce_sum( model.losses ) / hparams['batch_size']
  File "C:\Users\Rilwa\Anaconda3\lib\site-packages\tensorflow_core\python\util\dispatch.py", line 180, in wrapper
    return target(*args, **kwargs)
  File "C:\Users\Rilwa\Anaconda3\lib\site-packages\tensorflow_core\python\ops\math_ops.py", line 1611, in reduce_sum
    _ReductionDims(input_tensor, axis))
  File "C:\Users\Rilwa\Anaconda3\lib\site-packages\tensorflow_core\python\ops\math_ops.py", line 1496, in _ReductionDims
    return range(0, array_ops.rank(x))
  File "C:\Users\Rilwa\Anaconda3\lib\site-packages\tensorflow_core\python\util\dispatch.py", line 180, in wrapper
    return target(*args, **kwargs)
  File "C:\Users\Rilwa\Anaconda3\lib\site-packages\tensorflow_core\python\ops\array_ops.py", line 710, in rank
    return rank_internal(input, name, optimize=True)
  File "C:\Users\Rilwa\Anaconda3\lib\site-packages\tensorflow_core\python\ops\array_ops.py", line 730, in rank_internal
    input = ops.convert_to_tensor(input)
  File "C:\Users\Rilwa\Anaconda3\lib\site-packages\tensorflow_core\python\framework\ops.py", line 1314, in convert_to_tensor
    ret = conversion_func(value, dtype=dtype, name=name, as_ref=as_ref)
  File "C:\Users\Rilwa\Anaconda3\lib\site-packages\tensorflow_core\python\ops\array_ops.py", line 1377, in _autopacking_conversion_function
    return _autopacking_helper(v, dtype, name or "packed")
  File "C:\Users\Rilwa\Anaconda3\lib\site-packages\tensorflow_core\python\ops\array_ops.py", line 1283, in _autopacking_helper
    return gen_array_ops.pack(list_or_tuple, name=name)
  File "C:\Users\Rilwa\Anaconda3\lib\site-packages\tensorflow_core\python\ops\gen_array_ops.py", line 6264, in pack
    _ops.raise_from_not_ok_status(e, name)
  File "C:\Users\Rilwa\Anaconda3\lib\site-packages\tensorflow_core\python\framework\ops.py", line 6609, in raise_from_not_ok_status
    six.raise_from(core._status_to_exception(e.code, message), None)
  File "<string>", line 3, in raise_from
tensorflow.python.framework.errors_impl.InvalidArgumentError: Shapes of all inputs must match: values[0].shape = [] != values[1].shape = [1] [Op:Pack] name: packed



Error occured with last batch = 1Number of data per training batch = 10
Traceback (most recent call last):
  File "c:\Users\Rilwa\GoogleDrive\Warwick\PhD\ATI\BNN\layers_and_distributions.py", line 717, in train_loop
    df_training_info.to_csv( path_or_buf="/checkpoints/checkpoint_scores_model_{}.csv".format(train_params['model_version']), header=True, index=False )
  File "C:\Users\Rilwa\Anaconda3\lib\site-packages\pandas\core\generic.py", line 3229, in to_csv
    formatter.save()
  File "C:\Users\Rilwa\Anaconda3\lib\site-packages\pandas\io\formats\csvs.py", line 183, in save
    compression=self.compression,
  File "C:\Users\Rilwa\Anaconda3\lib\site-packages\pandas\io\common.py", line 397, in _get_handle
    f = open(path_or_buf, mode, encoding=encoding, newline="")
FileNotFoundError: [Errno 2] No such file or directory: '/checkpoints/checkpoint_scores_model_1.csv'



Error occured with last batch = 19Number of data per training batch = 10
Traceback (most recent call last):
  File "c:\Users\Rilwa\GoogleDrive\Warwick\PhD\ATI\BNN\layers_and_distributions.py", line 659, in train_loop
    preds = model( feature, tape=tape ) #TODO Debug, remove tape variable from model later
  File "C:\Users\Rilwa\Anaconda3\lib\site-packages\tensorflow_core\python\keras\engine\base_layer.py", line 822, in __call__
    outputs = self.call(cast_inputs, *args, **kwargs)
  File "c:\Users\Rilwa\GoogleDrive\Warwick\PhD\ATI\BNN\layers_and_distributions.py", line 52, in call
    x = self.SRCNN_1(inputs, tape=tape)
  File "C:\Users\Rilwa\Anaconda3\lib\site-packages\tensorflow_core\python\keras\engine\base_layer.py", line 822, in __call__
    outputs = self.call(cast_inputs, *args, **kwargs)
  File "c:\Users\Rilwa\GoogleDrive\Warwick\PhD\ATI\BNN\layers_and_distributions.py", line 110, in call
    self.update_posteriors_dists()
  File "c:\Users\Rilwa\GoogleDrive\Warwick\PhD\ATI\BNN\layers_and_distributions.py", line 211, in update_posteriors_dists
    conv2_betalogtau_post_scale = tf.linalg.cholesky(conv2_tf_U)
  File "C:\Users\Rilwa\Anaconda3\lib\site-packages\tensorflow_core\python\ops\gen_linalg_ops.py", line 712, in cholesky
    _ops.raise_from_not_ok_status(e, name)
  File "C:\Users\Rilwa\Anaconda3\lib\site-packages\tensorflow_core\python\framework\ops.py", line 6609, in raise_from_not_ok_status
    six.raise_from(core._status_to_exception(e.code, message), None)
  File "<string>", line 3, in raise_from
tensorflow.python.framework.errors_impl.InvalidArgumentError: Cholesky decomposition was not successful. The input might not be valid. [Op:Cholesky]



Error occured with last batch = 22Number of data per training batch = 10
Traceback (most recent call last):
  File "c:\Users\Rilwa\GoogleDrive\Warwick\PhD\ATI\BNN\layers_and_distributions.py", line 659, in train_loop
    preds = model( feature, tape=tape ) #TODO Debug, remove tape variable from model later
  File "C:\Users\Rilwa\Anaconda3\lib\site-packages\tensorflow_core\python\keras\engine\base_layer.py", line 822, in __call__
    outputs = self.call(cast_inputs, *args, **kwargs)
  File "c:\Users\Rilwa\GoogleDrive\Warwick\PhD\ATI\BNN\layers_and_distributions.py", line 52, in call
    x = self.SRCNN_1(inputs, tape=tape)
  File "C:\Users\Rilwa\Anaconda3\lib\site-packages\tensorflow_core\python\keras\engine\base_layer.py", line 822, in __call__
    outputs = self.call(cast_inputs, *args, **kwargs)
  File "c:\Users\Rilwa\GoogleDrive\Warwick\PhD\ATI\BNN\layers_and_distributions.py", line 110, in call
    self.update_posteriors_dists()
  File "c:\Users\Rilwa\GoogleDrive\Warwick\PhD\ATI\BNN\layers_and_distributions.py", line 211, in update_posteriors_dists
    conv2_betalogtau_post_scale = tf.linalg.cholesky(conv2_tf_U)
  File "C:\Users\Rilwa\Anaconda3\lib\site-packages\tensorflow_core\python\ops\gen_linalg_ops.py", line 712, in cholesky
    _ops.raise_from_not_ok_status(e, name)
  File "C:\Users\Rilwa\Anaconda3\lib\site-packages\tensorflow_core\python\framework\ops.py", line 6609, in raise_from_not_ok_status
    six.raise_from(core._status_to_exception(e.code, message), None)
  File "<string>", line 3, in raise_from
tensorflow.python.framework.errors_impl.InvalidArgumentError: Cholesky decomposition was not successful. The input might not be valid. [Op:Cholesky]



Error occured with last batch = 25Number of data per training batch = 10
Traceback (most recent call last):
  File "c:\Users\Rilwa\GoogleDrive\Warwick\PhD\ATI\BNN\layers_and_distributions.py", line 659, in train_loop
    preds = model( feature, tape=tape ) #TODO Debug, remove tape variable from model later
  File "C:\Users\Rilwa\Anaconda3\lib\site-packages\tensorflow_core\python\keras\engine\base_layer.py", line 822, in __call__
    outputs = self.call(cast_inputs, *args, **kwargs)
  File "c:\Users\Rilwa\GoogleDrive\Warwick\PhD\ATI\BNN\layers_and_distributions.py", line 52, in call
    x = self.SRCNN_1(inputs, tape=tape)
  File "C:\Users\Rilwa\Anaconda3\lib\site-packages\tensorflow_core\python\keras\engine\base_layer.py", line 822, in __call__
    outputs = self.call(cast_inputs, *args, **kwargs)
  File "c:\Users\Rilwa\GoogleDrive\Warwick\PhD\ATI\BNN\layers_and_distributions.py", line 110, in call
    self.update_posteriors_dists()
  File "c:\Users\Rilwa\GoogleDrive\Warwick\PhD\ATI\BNN\layers_and_distributions.py", line 211, in update_posteriors_dists
    conv2_betalogtau_post_scale = tf.linalg.cholesky(conv2_tf_U)
  File "C:\Users\Rilwa\Anaconda3\lib\site-packages\tensorflow_core\python\ops\gen_linalg_ops.py", line 712, in cholesky
    _ops.raise_from_not_ok_status(e, name)
  File "C:\Users\Rilwa\Anaconda3\lib\site-packages\tensorflow_core\python\framework\ops.py", line 6609, in raise_from_not_ok_status
    six.raise_from(core._status_to_exception(e.code, message), None)
  File "<string>", line 3, in raise_from
tensorflow.python.framework.errors_impl.InvalidArgumentError: Cholesky decomposition was not successful. The input might not be valid. [Op:Cholesky]



Error occured with last batch = 28Number of data per training batch = 10
Traceback (most recent call last):
  File "c:\Users\Rilwa\GoogleDrive\Warwick\PhD\ATI\BNN\layers_and_distributions.py", line 659, in train_loop
    preds = model( feature, tape=tape ) #TODO Debug, remove tape variable from model later
  File "C:\Users\Rilwa\Anaconda3\lib\site-packages\tensorflow_core\python\keras\engine\base_layer.py", line 822, in __call__
    outputs = self.call(cast_inputs, *args, **kwargs)
  File "c:\Users\Rilwa\GoogleDrive\Warwick\PhD\ATI\BNN\layers_and_distributions.py", line 52, in call
    x = self.SRCNN_1(inputs, tape=tape)
  File "C:\Users\Rilwa\Anaconda3\lib\site-packages\tensorflow_core\python\keras\engine\base_layer.py", line 822, in __call__
    outputs = self.call(cast_inputs, *args, **kwargs)
  File "c:\Users\Rilwa\GoogleDrive\Warwick\PhD\ATI\BNN\layers_and_distributions.py", line 110, in call
    self.update_posteriors_dists()
  File "c:\Users\Rilwa\GoogleDrive\Warwick\PhD\ATI\BNN\layers_and_distributions.py", line 211, in update_posteriors_dists
    conv2_betalogtau_post_scale = tf.linalg.cholesky(conv2_tf_U)
  File "C:\Users\Rilwa\Anaconda3\lib\site-packages\tensorflow_core\python\ops\gen_linalg_ops.py", line 712, in cholesky
    _ops.raise_from_not_ok_status(e, name)
  File "C:\Users\Rilwa\Anaconda3\lib\site-packages\tensorflow_core\python\framework\ops.py", line 6609, in raise_from_not_ok_status
    six.raise_from(core._status_to_exception(e.code, message), None)
  File "<string>", line 3, in raise_from
tensorflow.python.framework.errors_impl.InvalidArgumentError: Cholesky decomposition was not successful. The input might not be valid. [Op:Cholesky]



Error occured with last batch = 31Number of data per training batch = 10
Traceback (most recent call last):
  File "c:\Users\Rilwa\GoogleDrive\Warwick\PhD\ATI\BNN\layers_and_distributions.py", line 659, in train_loop
    preds = model( feature, tape=tape ) #TODO Debug, remove tape variable from model later
  File "C:\Users\Rilwa\Anaconda3\lib\site-packages\tensorflow_core\python\keras\engine\base_layer.py", line 822, in __call__
    outputs = self.call(cast_inputs, *args, **kwargs)
  File "c:\Users\Rilwa\GoogleDrive\Warwick\PhD\ATI\BNN\layers_and_distributions.py", line 52, in call
    x = self.SRCNN_1(inputs, tape=tape)
  File "C:\Users\Rilwa\Anaconda3\lib\site-packages\tensorflow_core\python\keras\engine\base_layer.py", line 822, in __call__
    outputs = self.call(cast_inputs, *args, **kwargs)
  File "c:\Users\Rilwa\GoogleDrive\Warwick\PhD\ATI\BNN\layers_and_distributions.py", line 110, in call
    self.update_posteriors_dists()
  File "c:\Users\Rilwa\GoogleDrive\Warwick\PhD\ATI\BNN\layers_and_distributions.py", line 211, in update_posteriors_dists
    conv2_betalogtau_post_scale = tf.linalg.cholesky(conv2_tf_U)
  File "C:\Users\Rilwa\Anaconda3\lib\site-packages\tensorflow_core\python\ops\gen_linalg_ops.py", line 712, in cholesky
    _ops.raise_from_not_ok_status(e, name)
  File "C:\Users\Rilwa\Anaconda3\lib\site-packages\tensorflow_core\python\framework\ops.py", line 6609, in raise_from_not_ok_status
    six.raise_from(core._status_to_exception(e.code, message), None)
  File "<string>", line 3, in raise_from
tensorflow.python.framework.errors_impl.InvalidArgumentError: Cholesky decomposition was not successful. The input might not be valid. [Op:Cholesky]



Error occured with last batch = 34Number of data per training batch = 10
Traceback (most recent call last):
  File "c:\Users\Rilwa\GoogleDrive\Warwick\PhD\ATI\BNN\layers_and_distributions.py", line 659, in train_loop
    preds = model( feature, tape=tape ) #TODO Debug, remove tape variable from model later
  File "C:\Users\Rilwa\Anaconda3\lib\site-packages\tensorflow_core\python\keras\engine\base_layer.py", line 822, in __call__
    outputs = self.call(cast_inputs, *args, **kwargs)
  File "c:\Users\Rilwa\GoogleDrive\Warwick\PhD\ATI\BNN\layers_and_distributions.py", line 52, in call
    x = self.SRCNN_1(inputs, tape=tape)
  File "C:\Users\Rilwa\Anaconda3\lib\site-packages\tensorflow_core\python\keras\engine\base_layer.py", line 822, in __call__
    outputs = self.call(cast_inputs, *args, **kwargs)
  File "c:\Users\Rilwa\GoogleDrive\Warwick\PhD\ATI\BNN\layers_and_distributions.py", line 110, in call
    self.update_posteriors_dists()
  File "c:\Users\Rilwa\GoogleDrive\Warwick\PhD\ATI\BNN\layers_and_distributions.py", line 211, in update_posteriors_dists
    conv2_betalogtau_post_scale = tf.linalg.cholesky(conv2_tf_U)
  File "C:\Users\Rilwa\Anaconda3\lib\site-packages\tensorflow_core\python\ops\gen_linalg_ops.py", line 712, in cholesky
    _ops.raise_from_not_ok_status(e, name)
  File "C:\Users\Rilwa\Anaconda3\lib\site-packages\tensorflow_core\python\framework\ops.py", line 6609, in raise_from_not_ok_status
    six.raise_from(core._status_to_exception(e.code, message), None)
  File "<string>", line 3, in raise_from
tensorflow.python.framework.errors_impl.InvalidArgumentError: Cholesky decomposition was not successful. The input might not be valid. [Op:Cholesky]



Error occured with last batch = 37Number of data per training batch = 10
Traceback (most recent call last):
  File "c:\Users\Rilwa\GoogleDrive\Warwick\PhD\ATI\BNN\layers_and_distributions.py", line 659, in train_loop
    preds = model( feature, tape=tape ) #TODO Debug, remove tape variable from model later
  File "C:\Users\Rilwa\Anaconda3\lib\site-packages\tensorflow_core\python\keras\engine\base_layer.py", line 822, in __call__
    outputs = self.call(cast_inputs, *args, **kwargs)
  File "c:\Users\Rilwa\GoogleDrive\Warwick\PhD\ATI\BNN\layers_and_distributions.py", line 52, in call
    x = self.SRCNN_1(inputs, tape=tape)
  File "C:\Users\Rilwa\Anaconda3\lib\site-packages\tensorflow_core\python\keras\engine\base_layer.py", line 822, in __call__
    outputs = self.call(cast_inputs, *args, **kwargs)
  File "c:\Users\Rilwa\GoogleDrive\Warwick\PhD\ATI\BNN\layers_and_distributions.py", line 110, in call
    self.update_posteriors_dists()
  File "c:\Users\Rilwa\GoogleDrive\Warwick\PhD\ATI\BNN\layers_and_distributions.py", line 211, in update_posteriors_dists
    conv2_betalogtau_post_scale = tf.linalg.cholesky(conv2_tf_U)
  File "C:\Users\Rilwa\Anaconda3\lib\site-packages\tensorflow_core\python\ops\gen_linalg_ops.py", line 712, in cholesky
    _ops.raise_from_not_ok_status(e, name)
  File "C:\Users\Rilwa\Anaconda3\lib\site-packages\tensorflow_core\python\framework\ops.py", line 6609, in raise_from_not_ok_status
    six.raise_from(core._status_to_exception(e.code, message), None)
  File "<string>", line 3, in raise_from
tensorflow.python.framework.errors_impl.InvalidArgumentError: Cholesky decomposition was not successful. The input might not be valid. [Op:Cholesky]



Error occured with last batch = 40Number of data per training batch = 10
Traceback (most recent call last):
  File "c:\Users\Rilwa\GoogleDrive\Warwick\PhD\ATI\BNN\layers_and_distributions.py", line 659, in train_loop
    preds = model( feature, tape=tape ) #TODO Debug, remove tape variable from model later
  File "C:\Users\Rilwa\Anaconda3\lib\site-packages\tensorflow_core\python\keras\engine\base_layer.py", line 822, in __call__
    outputs = self.call(cast_inputs, *args, **kwargs)
  File "c:\Users\Rilwa\GoogleDrive\Warwick\PhD\ATI\BNN\layers_and_distributions.py", line 52, in call
    x = self.SRCNN_1(inputs, tape=tape)
  File "C:\Users\Rilwa\Anaconda3\lib\site-packages\tensorflow_core\python\keras\engine\base_layer.py", line 822, in __call__
    outputs = self.call(cast_inputs, *args, **kwargs)
  File "c:\Users\Rilwa\GoogleDrive\Warwick\PhD\ATI\BNN\layers_and_distributions.py", line 110, in call
    self.update_posteriors_dists()
  File "c:\Users\Rilwa\GoogleDrive\Warwick\PhD\ATI\BNN\layers_and_distributions.py", line 211, in update_posteriors_dists
    conv2_betalogtau_post_scale = tf.linalg.cholesky(conv2_tf_U)
  File "C:\Users\Rilwa\Anaconda3\lib\site-packages\tensorflow_core\python\ops\gen_linalg_ops.py", line 712, in cholesky
    _ops.raise_from_not_ok_status(e, name)
  File "C:\Users\Rilwa\Anaconda3\lib\site-packages\tensorflow_core\python\framework\ops.py", line 6609, in raise_from_not_ok_status
    six.raise_from(core._status_to_exception(e.code, message), None)
  File "<string>", line 3, in raise_from
tensorflow.python.framework.errors_impl.InvalidArgumentError: Cholesky decomposition was not successful. The input might not be valid. [Op:Cholesky]



Error occured with last batch = 43Number of data per training batch = 10
Traceback (most recent call last):
  File "c:\Users\Rilwa\GoogleDrive\Warwick\PhD\ATI\BNN\layers_and_distributions.py", line 659, in train_loop
    preds = model( feature, tape=tape ) #TODO Debug, remove tape variable from model later
  File "C:\Users\Rilwa\Anaconda3\lib\site-packages\tensorflow_core\python\keras\engine\base_layer.py", line 822, in __call__
    outputs = self.call(cast_inputs, *args, **kwargs)
  File "c:\Users\Rilwa\GoogleDrive\Warwick\PhD\ATI\BNN\layers_and_distributions.py", line 52, in call
    x = self.SRCNN_1(inputs, tape=tape)
  File "C:\Users\Rilwa\Anaconda3\lib\site-packages\tensorflow_core\python\keras\engine\base_layer.py", line 822, in __call__
    outputs = self.call(cast_inputs, *args, **kwargs)
  File "c:\Users\Rilwa\GoogleDrive\Warwick\PhD\ATI\BNN\layers_and_distributions.py", line 110, in call
    self.update_posteriors_dists()
  File "c:\Users\Rilwa\GoogleDrive\Warwick\PhD\ATI\BNN\layers_and_distributions.py", line 211, in update_posteriors_dists
    conv2_betalogtau_post_scale = tf.linalg.cholesky(conv2_tf_U)
  File "C:\Users\Rilwa\Anaconda3\lib\site-packages\tensorflow_core\python\ops\gen_linalg_ops.py", line 712, in cholesky
    _ops.raise_from_not_ok_status(e, name)
  File "C:\Users\Rilwa\Anaconda3\lib\site-packages\tensorflow_core\python\framework\ops.py", line 6609, in raise_from_not_ok_status
    six.raise_from(core._status_to_exception(e.code, message), None)
  File "<string>", line 3, in raise_from
tensorflow.python.framework.errors_impl.InvalidArgumentError: Cholesky decomposition was not successful. The input might not be valid. [Op:Cholesky]



Error occured with last batch = 46Number of data per training batch = 10
Traceback (most recent call last):
  File "c:\Users\Rilwa\GoogleDrive\Warwick\PhD\ATI\BNN\layers_and_distributions.py", line 659, in train_loop
    preds = model( feature, tape=tape ) #TODO Debug, remove tape variable from model later
  File "C:\Users\Rilwa\Anaconda3\lib\site-packages\tensorflow_core\python\keras\engine\base_layer.py", line 822, in __call__
    outputs = self.call(cast_inputs, *args, **kwargs)
  File "c:\Users\Rilwa\GoogleDrive\Warwick\PhD\ATI\BNN\layers_and_distributions.py", line 52, in call
    x = self.SRCNN_1(inputs, tape=tape)
  File "C:\Users\Rilwa\Anaconda3\lib\site-packages\tensorflow_core\python\keras\engine\base_layer.py", line 822, in __call__
    outputs = self.call(cast_inputs, *args, **kwargs)
  File "c:\Users\Rilwa\GoogleDrive\Warwick\PhD\ATI\BNN\layers_and_distributions.py", line 110, in call
    self.update_posteriors_dists()
  File "c:\Users\Rilwa\GoogleDrive\Warwick\PhD\ATI\BNN\layers_and_distributions.py", line 211, in update_posteriors_dists
    conv2_betalogtau_post_scale = tf.linalg.cholesky(conv2_tf_U)
  File "C:\Users\Rilwa\Anaconda3\lib\site-packages\tensorflow_core\python\ops\gen_linalg_ops.py", line 712, in cholesky
    _ops.raise_from_not_ok_status(e, name)
  File "C:\Users\Rilwa\Anaconda3\lib\site-packages\tensorflow_core\python\framework\ops.py", line 6609, in raise_from_not_ok_status
    six.raise_from(core._status_to_exception(e.code, message), None)
  File "<string>", line 3, in raise_from
tensorflow.python.framework.errors_impl.InvalidArgumentError: Cholesky decomposition was not successful. The input might not be valid. [Op:Cholesky]



Error occured with last batch = 49Number of data per training batch = 10
Traceback (most recent call last):
  File "c:\Users\Rilwa\GoogleDrive\Warwick\PhD\ATI\BNN\layers_and_distributions.py", line 659, in train_loop
    preds = model( feature, tape=tape ) #TODO Debug, remove tape variable from model later
  File "C:\Users\Rilwa\Anaconda3\lib\site-packages\tensorflow_core\python\keras\engine\base_layer.py", line 822, in __call__
    outputs = self.call(cast_inputs, *args, **kwargs)
  File "c:\Users\Rilwa\GoogleDrive\Warwick\PhD\ATI\BNN\layers_and_distributions.py", line 52, in call
    x = self.SRCNN_1(inputs, tape=tape)
  File "C:\Users\Rilwa\Anaconda3\lib\site-packages\tensorflow_core\python\keras\engine\base_layer.py", line 822, in __call__
    outputs = self.call(cast_inputs, *args, **kwargs)
  File "c:\Users\Rilwa\GoogleDrive\Warwick\PhD\ATI\BNN\layers_and_distributions.py", line 110, in call
    self.update_posteriors_dists()
  File "c:\Users\Rilwa\GoogleDrive\Warwick\PhD\ATI\BNN\layers_and_distributions.py", line 211, in update_posteriors_dists
    conv2_betalogtau_post_scale = tf.linalg.cholesky(conv2_tf_U)
  File "C:\Users\Rilwa\Anaconda3\lib\site-packages\tensorflow_core\python\ops\gen_linalg_ops.py", line 712, in cholesky
    _ops.raise_from_not_ok_status(e, name)
  File "C:\Users\Rilwa\Anaconda3\lib\site-packages\tensorflow_core\python\framework\ops.py", line 6609, in raise_from_not_ok_status
    six.raise_from(core._status_to_exception(e.code, message), None)
  File "<string>", line 3, in raise_from
tensorflow.python.framework.errors_impl.InvalidArgumentError: Cholesky decomposition was not successful. The input might not be valid. [Op:Cholesky]



Error occured with last batch = 52Number of data per training batch = 10
Traceback (most recent call last):
  File "c:\Users\Rilwa\GoogleDrive\Warwick\PhD\ATI\BNN\layers_and_distributions.py", line 659, in train_loop
    preds = model( feature, tape=tape ) #TODO Debug, remove tape variable from model later
  File "C:\Users\Rilwa\Anaconda3\lib\site-packages\tensorflow_core\python\keras\engine\base_layer.py", line 822, in __call__
    outputs = self.call(cast_inputs, *args, **kwargs)
  File "c:\Users\Rilwa\GoogleDrive\Warwick\PhD\ATI\BNN\layers_and_distributions.py", line 52, in call
    x = self.SRCNN_1(inputs, tape=tape)
  File "C:\Users\Rilwa\Anaconda3\lib\site-packages\tensorflow_core\python\keras\engine\base_layer.py", line 822, in __call__
    outputs = self.call(cast_inputs, *args, **kwargs)
  File "c:\Users\Rilwa\GoogleDrive\Warwick\PhD\ATI\BNN\layers_and_distributions.py", line 110, in call
    self.update_posteriors_dists()
  File "c:\Users\Rilwa\GoogleDrive\Warwick\PhD\ATI\BNN\layers_and_distributions.py", line 211, in update_posteriors_dists
    conv2_betalogtau_post_scale = tf.linalg.cholesky(conv2_tf_U)
  File "C:\Users\Rilwa\Anaconda3\lib\site-packages\tensorflow_core\python\ops\gen_linalg_ops.py", line 712, in cholesky
    _ops.raise_from_not_ok_status(e, name)
  File "C:\Users\Rilwa\Anaconda3\lib\site-packages\tensorflow_core\python\framework\ops.py", line 6609, in raise_from_not_ok_status
    six.raise_from(core._status_to_exception(e.code, message), None)
  File "<string>", line 3, in raise_from
tensorflow.python.framework.errors_impl.InvalidArgumentError: Cholesky decomposition was not successful. The input might not be valid. [Op:Cholesky]



Error occured with last batch = 55Number of data per training batch = 10
Traceback (most recent call last):
  File "c:\Users\Rilwa\GoogleDrive\Warwick\PhD\ATI\BNN\layers_and_distributions.py", line 659, in train_loop
    preds = model( feature, tape=tape ) #TODO Debug, remove tape variable from model later
  File "C:\Users\Rilwa\Anaconda3\lib\site-packages\tensorflow_core\python\keras\engine\base_layer.py", line 822, in __call__
    outputs = self.call(cast_inputs, *args, **kwargs)
  File "c:\Users\Rilwa\GoogleDrive\Warwick\PhD\ATI\BNN\layers_and_distributions.py", line 52, in call
    x = self.SRCNN_1(inputs, tape=tape)
  File "C:\Users\Rilwa\Anaconda3\lib\site-packages\tensorflow_core\python\keras\engine\base_layer.py", line 822, in __call__
    outputs = self.call(cast_inputs, *args, **kwargs)
  File "c:\Users\Rilwa\GoogleDrive\Warwick\PhD\ATI\BNN\layers_and_distributions.py", line 110, in call
    self.update_posteriors_dists()
  File "c:\Users\Rilwa\GoogleDrive\Warwick\PhD\ATI\BNN\layers_and_distributions.py", line 211, in update_posteriors_dists
    conv2_betalogtau_post_scale = tf.linalg.cholesky(conv2_tf_U)
  File "C:\Users\Rilwa\Anaconda3\lib\site-packages\tensorflow_core\python\ops\gen_linalg_ops.py", line 712, in cholesky
    _ops.raise_from_not_ok_status(e, name)
  File "C:\Users\Rilwa\Anaconda3\lib\site-packages\tensorflow_core\python\framework\ops.py", line 6609, in raise_from_not_ok_status
    six.raise_from(core._status_to_exception(e.code, message), None)
  File "<string>", line 3, in raise_from
tensorflow.python.framework.errors_impl.InvalidArgumentError: Cholesky decomposition was not successful. The input might not be valid. [Op:Cholesky]



Error occured with last batch = 58Number of data per training batch = 10
Traceback (most recent call last):
  File "c:\Users\Rilwa\GoogleDrive\Warwick\PhD\ATI\BNN\layers_and_distributions.py", line 659, in train_loop
    preds = model( feature, tape=tape ) #TODO Debug, remove tape variable from model later
  File "C:\Users\Rilwa\Anaconda3\lib\site-packages\tensorflow_core\python\keras\engine\base_layer.py", line 822, in __call__
    outputs = self.call(cast_inputs, *args, **kwargs)
  File "c:\Users\Rilwa\GoogleDrive\Warwick\PhD\ATI\BNN\layers_and_distributions.py", line 52, in call
    x = self.SRCNN_1(inputs, tape=tape)
  File "C:\Users\Rilwa\Anaconda3\lib\site-packages\tensorflow_core\python\keras\engine\base_layer.py", line 822, in __call__
    outputs = self.call(cast_inputs, *args, **kwargs)
  File "c:\Users\Rilwa\GoogleDrive\Warwick\PhD\ATI\BNN\layers_and_distributions.py", line 110, in call
    self.update_posteriors_dists()
  File "c:\Users\Rilwa\GoogleDrive\Warwick\PhD\ATI\BNN\layers_and_distributions.py", line 211, in update_posteriors_dists
    conv2_betalogtau_post_scale = tf.linalg.cholesky(conv2_tf_U)
  File "C:\Users\Rilwa\Anaconda3\lib\site-packages\tensorflow_core\python\ops\gen_linalg_ops.py", line 712, in cholesky
    _ops.raise_from_not_ok_status(e, name)
  File "C:\Users\Rilwa\Anaconda3\lib\site-packages\tensorflow_core\python\framework\ops.py", line 6609, in raise_from_not_ok_status
    six.raise_from(core._status_to_exception(e.code, message), None)
  File "<string>", line 3, in raise_from
tensorflow.python.framework.errors_impl.InvalidArgumentError: Cholesky decomposition was not successful. The input might not be valid. [Op:Cholesky]



Error occured with last batch = 61Number of data per training batch = 10
Traceback (most recent call last):
  File "c:\Users\Rilwa\GoogleDrive\Warwick\PhD\ATI\BNN\layers_and_distributions.py", line 659, in train_loop
    preds = model( feature, tape=tape ) #TODO Debug, remove tape variable from model later
  File "C:\Users\Rilwa\Anaconda3\lib\site-packages\tensorflow_core\python\keras\engine\base_layer.py", line 822, in __call__
    outputs = self.call(cast_inputs, *args, **kwargs)
  File "c:\Users\Rilwa\GoogleDrive\Warwick\PhD\ATI\BNN\layers_and_distributions.py", line 52, in call
    x = self.SRCNN_1(inputs, tape=tape)
  File "C:\Users\Rilwa\Anaconda3\lib\site-packages\tensorflow_core\python\keras\engine\base_layer.py", line 822, in __call__
    outputs = self.call(cast_inputs, *args, **kwargs)
  File "c:\Users\Rilwa\GoogleDrive\Warwick\PhD\ATI\BNN\layers_and_distributions.py", line 110, in call
    self.update_posteriors_dists()
  File "c:\Users\Rilwa\GoogleDrive\Warwick\PhD\ATI\BNN\layers_and_distributions.py", line 211, in update_posteriors_dists
    conv2_betalogtau_post_scale = tf.linalg.cholesky(conv2_tf_U)
  File "C:\Users\Rilwa\Anaconda3\lib\site-packages\tensorflow_core\python\ops\gen_linalg_ops.py", line 712, in cholesky
    _ops.raise_from_not_ok_status(e, name)
  File "C:\Users\Rilwa\Anaconda3\lib\site-packages\tensorflow_core\python\framework\ops.py", line 6609, in raise_from_not_ok_status
    six.raise_from(core._status_to_exception(e.code, message), None)
  File "<string>", line 3, in raise_from
tensorflow.python.framework.errors_impl.InvalidArgumentError: Cholesky decomposition was not successful. The input might not be valid. [Op:Cholesky]



Error occured with last batch = 64Number of data per training batch = 10
Traceback (most recent call last):
  File "c:\Users\Rilwa\GoogleDrive\Warwick\PhD\ATI\BNN\layers_and_distributions.py", line 659, in train_loop
    preds = model( feature, tape=tape ) #TODO Debug, remove tape variable from model later
  File "C:\Users\Rilwa\Anaconda3\lib\site-packages\tensorflow_core\python\keras\engine\base_layer.py", line 822, in __call__
    outputs = self.call(cast_inputs, *args, **kwargs)
  File "c:\Users\Rilwa\GoogleDrive\Warwick\PhD\ATI\BNN\layers_and_distributions.py", line 52, in call
    x = self.SRCNN_1(inputs, tape=tape)
  File "C:\Users\Rilwa\Anaconda3\lib\site-packages\tensorflow_core\python\keras\engine\base_layer.py", line 822, in __call__
    outputs = self.call(cast_inputs, *args, **kwargs)
  File "c:\Users\Rilwa\GoogleDrive\Warwick\PhD\ATI\BNN\layers_and_distributions.py", line 110, in call
    self.update_posteriors_dists()
  File "c:\Users\Rilwa\GoogleDrive\Warwick\PhD\ATI\BNN\layers_and_distributions.py", line 211, in update_posteriors_dists
    conv2_betalogtau_post_scale = tf.linalg.cholesky(conv2_tf_U)
  File "C:\Users\Rilwa\Anaconda3\lib\site-packages\tensorflow_core\python\ops\gen_linalg_ops.py", line 712, in cholesky
    _ops.raise_from_not_ok_status(e, name)
  File "C:\Users\Rilwa\Anaconda3\lib\site-packages\tensorflow_core\python\framework\ops.py", line 6609, in raise_from_not_ok_status
    six.raise_from(core._status_to_exception(e.code, message), None)
  File "<string>", line 3, in raise_from
tensorflow.python.framework.errors_impl.InvalidArgumentError: Cholesky decomposition was not successful. The input might not be valid. [Op:Cholesky]



Error occured with last batch = 67Number of data per training batch = 10
Traceback (most recent call last):
  File "c:\Users\Rilwa\GoogleDrive\Warwick\PhD\ATI\BNN\layers_and_distributions.py", line 659, in train_loop
    preds = model( feature, tape=tape ) #TODO Debug, remove tape variable from model later
  File "C:\Users\Rilwa\Anaconda3\lib\site-packages\tensorflow_core\python\keras\engine\base_layer.py", line 822, in __call__
    outputs = self.call(cast_inputs, *args, **kwargs)
  File "c:\Users\Rilwa\GoogleDrive\Warwick\PhD\ATI\BNN\layers_and_distributions.py", line 52, in call
    x = self.SRCNN_1(inputs, tape=tape)
  File "C:\Users\Rilwa\Anaconda3\lib\site-packages\tensorflow_core\python\keras\engine\base_layer.py", line 822, in __call__
    outputs = self.call(cast_inputs, *args, **kwargs)
  File "c:\Users\Rilwa\GoogleDrive\Warwick\PhD\ATI\BNN\layers_and_distributions.py", line 110, in call
    self.update_posteriors_dists()
  File "c:\Users\Rilwa\GoogleDrive\Warwick\PhD\ATI\BNN\layers_and_distributions.py", line 211, in update_posteriors_dists
    conv2_betalogtau_post_scale = tf.linalg.cholesky(conv2_tf_U)
  File "C:\Users\Rilwa\Anaconda3\lib\site-packages\tensorflow_core\python\ops\gen_linalg_ops.py", line 712, in cholesky
    _ops.raise_from_not_ok_status(e, name)
  File "C:\Users\Rilwa\Anaconda3\lib\site-packages\tensorflow_core\python\framework\ops.py", line 6609, in raise_from_not_ok_status
    six.raise_from(core._status_to_exception(e.code, message), None)
  File "<string>", line 3, in raise_from
tensorflow.python.framework.errors_impl.InvalidArgumentError: Cholesky decomposition was not successful. The input might not be valid. [Op:Cholesky]



Error occured with last batch = 70Number of data per training batch = 10
Traceback (most recent call last):
  File "c:\Users\Rilwa\GoogleDrive\Warwick\PhD\ATI\BNN\layers_and_distributions.py", line 659, in train_loop
    preds = model( feature, tape=tape ) #TODO Debug, remove tape variable from model later
  File "C:\Users\Rilwa\Anaconda3\lib\site-packages\tensorflow_core\python\keras\engine\base_layer.py", line 822, in __call__
    outputs = self.call(cast_inputs, *args, **kwargs)
  File "c:\Users\Rilwa\GoogleDrive\Warwick\PhD\ATI\BNN\layers_and_distributions.py", line 52, in call
    x = self.SRCNN_1(inputs, tape=tape)
  File "C:\Users\Rilwa\Anaconda3\lib\site-packages\tensorflow_core\python\keras\engine\base_layer.py", line 822, in __call__
    outputs = self.call(cast_inputs, *args, **kwargs)
  File "c:\Users\Rilwa\GoogleDrive\Warwick\PhD\ATI\BNN\layers_and_distributions.py", line 110, in call
    self.update_posteriors_dists()
  File "c:\Users\Rilwa\GoogleDrive\Warwick\PhD\ATI\BNN\layers_and_distributions.py", line 211, in update_posteriors_dists
    conv2_betalogtau_post_scale = tf.linalg.cholesky(conv2_tf_U)
  File "C:\Users\Rilwa\Anaconda3\lib\site-packages\tensorflow_core\python\ops\gen_linalg_ops.py", line 712, in cholesky
    _ops.raise_from_not_ok_status(e, name)
  File "C:\Users\Rilwa\Anaconda3\lib\site-packages\tensorflow_core\python\framework\ops.py", line 6609, in raise_from_not_ok_status
    six.raise_from(core._status_to_exception(e.code, message), None)
  File "<string>", line 3, in raise_from
tensorflow.python.framework.errors_impl.InvalidArgumentError: Cholesky decomposition was not successful. The input might not be valid. [Op:Cholesky]



Error occured with last batch = 73Number of data per training batch = 10
Traceback (most recent call last):
  File "c:\Users\Rilwa\GoogleDrive\Warwick\PhD\ATI\BNN\layers_and_distributions.py", line 659, in train_loop
    preds = model( feature, tape=tape ) #TODO Debug, remove tape variable from model later
  File "C:\Users\Rilwa\Anaconda3\lib\site-packages\tensorflow_core\python\keras\engine\base_layer.py", line 822, in __call__
    outputs = self.call(cast_inputs, *args, **kwargs)
  File "c:\Users\Rilwa\GoogleDrive\Warwick\PhD\ATI\BNN\layers_and_distributions.py", line 52, in call
    x = self.SRCNN_1(inputs, tape=tape)
  File "C:\Users\Rilwa\Anaconda3\lib\site-packages\tensorflow_core\python\keras\engine\base_layer.py", line 822, in __call__
    outputs = self.call(cast_inputs, *args, **kwargs)
  File "c:\Users\Rilwa\GoogleDrive\Warwick\PhD\ATI\BNN\layers_and_distributions.py", line 110, in call
    self.update_posteriors_dists()
  File "c:\Users\Rilwa\GoogleDrive\Warwick\PhD\ATI\BNN\layers_and_distributions.py", line 211, in update_posteriors_dists
    conv2_betalogtau_post_scale = tf.linalg.cholesky(conv2_tf_U)
  File "C:\Users\Rilwa\Anaconda3\lib\site-packages\tensorflow_core\python\ops\gen_linalg_ops.py", line 712, in cholesky
    _ops.raise_from_not_ok_status(e, name)
  File "C:\Users\Rilwa\Anaconda3\lib\site-packages\tensorflow_core\python\framework\ops.py", line 6609, in raise_from_not_ok_status
    six.raise_from(core._status_to_exception(e.code, message), None)
  File "<string>", line 3, in raise_from
tensorflow.python.framework.errors_impl.InvalidArgumentError: Cholesky decomposition was not successful. The input might not be valid. [Op:Cholesky]



Error occured with last batch = 76Number of data per training batch = 10
Traceback (most recent call last):
  File "c:\Users\Rilwa\GoogleDrive\Warwick\PhD\ATI\BNN\layers_and_distributions.py", line 659, in train_loop
    preds = model( feature, tape=tape ) #TODO Debug, remove tape variable from model later
  File "C:\Users\Rilwa\Anaconda3\lib\site-packages\tensorflow_core\python\keras\engine\base_layer.py", line 822, in __call__
    outputs = self.call(cast_inputs, *args, **kwargs)
  File "c:\Users\Rilwa\GoogleDrive\Warwick\PhD\ATI\BNN\layers_and_distributions.py", line 52, in call
    x = self.SRCNN_1(inputs, tape=tape)
  File "C:\Users\Rilwa\Anaconda3\lib\site-packages\tensorflow_core\python\keras\engine\base_layer.py", line 822, in __call__
    outputs = self.call(cast_inputs, *args, **kwargs)
  File "c:\Users\Rilwa\GoogleDrive\Warwick\PhD\ATI\BNN\layers_and_distributions.py", line 110, in call
    self.update_posteriors_dists()
  File "c:\Users\Rilwa\GoogleDrive\Warwick\PhD\ATI\BNN\layers_and_distributions.py", line 211, in update_posteriors_dists
    conv2_betalogtau_post_scale = tf.linalg.cholesky(conv2_tf_U)
  File "C:\Users\Rilwa\Anaconda3\lib\site-packages\tensorflow_core\python\ops\gen_linalg_ops.py", line 712, in cholesky
    _ops.raise_from_not_ok_status(e, name)
  File "C:\Users\Rilwa\Anaconda3\lib\site-packages\tensorflow_core\python\framework\ops.py", line 6609, in raise_from_not_ok_status
    six.raise_from(core._status_to_exception(e.code, message), None)
  File "<string>", line 3, in raise_from
tensorflow.python.framework.errors_impl.InvalidArgumentError: Cholesky decomposition was not successful. The input might not be valid. [Op:Cholesky]



Error occured with last batch = 79Number of data per training batch = 10
Traceback (most recent call last):
  File "c:\Users\Rilwa\GoogleDrive\Warwick\PhD\ATI\BNN\layers_and_distributions.py", line 659, in train_loop
    preds = model( feature, tape=tape ) #TODO Debug, remove tape variable from model later
  File "C:\Users\Rilwa\Anaconda3\lib\site-packages\tensorflow_core\python\keras\engine\base_layer.py", line 822, in __call__
    outputs = self.call(cast_inputs, *args, **kwargs)
  File "c:\Users\Rilwa\GoogleDrive\Warwick\PhD\ATI\BNN\layers_and_distributions.py", line 52, in call
    x = self.SRCNN_1(inputs, tape=tape)
  File "C:\Users\Rilwa\Anaconda3\lib\site-packages\tensorflow_core\python\keras\engine\base_layer.py", line 822, in __call__
    outputs = self.call(cast_inputs, *args, **kwargs)
  File "c:\Users\Rilwa\GoogleDrive\Warwick\PhD\ATI\BNN\layers_and_distributions.py", line 110, in call
    self.update_posteriors_dists()
  File "c:\Users\Rilwa\GoogleDrive\Warwick\PhD\ATI\BNN\layers_and_distributions.py", line 211, in update_posteriors_dists
    conv2_betalogtau_post_scale = tf.linalg.cholesky(conv2_tf_U)
  File "C:\Users\Rilwa\Anaconda3\lib\site-packages\tensorflow_core\python\ops\gen_linalg_ops.py", line 712, in cholesky
    _ops.raise_from_not_ok_status(e, name)
  File "C:\Users\Rilwa\Anaconda3\lib\site-packages\tensorflow_core\python\framework\ops.py", line 6609, in raise_from_not_ok_status
    six.raise_from(core._status_to_exception(e.code, message), None)
  File "<string>", line 3, in raise_from
tensorflow.python.framework.errors_impl.InvalidArgumentError: Cholesky decomposition was not successful. The input might not be valid. [Op:Cholesky]



Error occured with last batch = 82Number of data per training batch = 10
Traceback (most recent call last):
  File "c:\Users\Rilwa\GoogleDrive\Warwick\PhD\ATI\BNN\layers_and_distributions.py", line 659, in train_loop
    preds = model( feature, tape=tape ) #TODO Debug, remove tape variable from model later
  File "C:\Users\Rilwa\Anaconda3\lib\site-packages\tensorflow_core\python\keras\engine\base_layer.py", line 822, in __call__
    outputs = self.call(cast_inputs, *args, **kwargs)
  File "c:\Users\Rilwa\GoogleDrive\Warwick\PhD\ATI\BNN\layers_and_distributions.py", line 52, in call
    x = self.SRCNN_1(inputs, tape=tape)
  File "C:\Users\Rilwa\Anaconda3\lib\site-packages\tensorflow_core\python\keras\engine\base_layer.py", line 822, in __call__
    outputs = self.call(cast_inputs, *args, **kwargs)
  File "c:\Users\Rilwa\GoogleDrive\Warwick\PhD\ATI\BNN\layers_and_distributions.py", line 110, in call
    self.update_posteriors_dists()
  File "c:\Users\Rilwa\GoogleDrive\Warwick\PhD\ATI\BNN\layers_and_distributions.py", line 211, in update_posteriors_dists
    conv2_betalogtau_post_scale = tf.linalg.cholesky(conv2_tf_U)
  File "C:\Users\Rilwa\Anaconda3\lib\site-packages\tensorflow_core\python\ops\gen_linalg_ops.py", line 712, in cholesky
    _ops.raise_from_not_ok_status(e, name)
  File "C:\Users\Rilwa\Anaconda3\lib\site-packages\tensorflow_core\python\framework\ops.py", line 6609, in raise_from_not_ok_status
    six.raise_from(core._status_to_exception(e.code, message), None)
  File "<string>", line 3, in raise_from
tensorflow.python.framework.errors_impl.InvalidArgumentError: Cholesky decomposition was not successful. The input might not be valid. [Op:Cholesky]



Error occured with last batch = 85Number of data per training batch = 10
Traceback (most recent call last):
  File "c:\Users\Rilwa\GoogleDrive\Warwick\PhD\ATI\BNN\layers_and_distributions.py", line 659, in train_loop
    preds = model( feature, tape=tape ) #TODO Debug, remove tape variable from model later
  File "C:\Users\Rilwa\Anaconda3\lib\site-packages\tensorflow_core\python\keras\engine\base_layer.py", line 822, in __call__
    outputs = self.call(cast_inputs, *args, **kwargs)
  File "c:\Users\Rilwa\GoogleDrive\Warwick\PhD\ATI\BNN\layers_and_distributions.py", line 52, in call
    x = self.SRCNN_1(inputs, tape=tape)
  File "C:\Users\Rilwa\Anaconda3\lib\site-packages\tensorflow_core\python\keras\engine\base_layer.py", line 822, in __call__
    outputs = self.call(cast_inputs, *args, **kwargs)
  File "c:\Users\Rilwa\GoogleDrive\Warwick\PhD\ATI\BNN\layers_and_distributions.py", line 110, in call
    self.update_posteriors_dists()
  File "c:\Users\Rilwa\GoogleDrive\Warwick\PhD\ATI\BNN\layers_and_distributions.py", line 211, in update_posteriors_dists
    conv2_betalogtau_post_scale = tf.linalg.cholesky(conv2_tf_U)
  File "C:\Users\Rilwa\Anaconda3\lib\site-packages\tensorflow_core\python\ops\gen_linalg_ops.py", line 712, in cholesky
    _ops.raise_from_not_ok_status(e, name)
  File "C:\Users\Rilwa\Anaconda3\lib\site-packages\tensorflow_core\python\framework\ops.py", line 6609, in raise_from_not_ok_status
    six.raise_from(core._status_to_exception(e.code, message), None)
  File "<string>", line 3, in raise_from
tensorflow.python.framework.errors_impl.InvalidArgumentError: Cholesky decomposition was not successful. The input might not be valid. [Op:Cholesky]



Error occured with last batch = 88Number of data per training batch = 10
Traceback (most recent call last):
  File "c:\Users\Rilwa\GoogleDrive\Warwick\PhD\ATI\BNN\layers_and_distributions.py", line 659, in train_loop
    preds = model( feature, tape=tape ) #TODO Debug, remove tape variable from model later
  File "C:\Users\Rilwa\Anaconda3\lib\site-packages\tensorflow_core\python\keras\engine\base_layer.py", line 822, in __call__
    outputs = self.call(cast_inputs, *args, **kwargs)
  File "c:\Users\Rilwa\GoogleDrive\Warwick\PhD\ATI\BNN\layers_and_distributions.py", line 52, in call
    x = self.SRCNN_1(inputs, tape=tape)
  File "C:\Users\Rilwa\Anaconda3\lib\site-packages\tensorflow_core\python\keras\engine\base_layer.py", line 822, in __call__
    outputs = self.call(cast_inputs, *args, **kwargs)
  File "c:\Users\Rilwa\GoogleDrive\Warwick\PhD\ATI\BNN\layers_and_distributions.py", line 110, in call
    self.update_posteriors_dists()
  File "c:\Users\Rilwa\GoogleDrive\Warwick\PhD\ATI\BNN\layers_and_distributions.py", line 211, in update_posteriors_dists
    conv2_betalogtau_post_scale = tf.linalg.cholesky(conv2_tf_U)
  File "C:\Users\Rilwa\Anaconda3\lib\site-packages\tensorflow_core\python\ops\gen_linalg_ops.py", line 712, in cholesky
    _ops.raise_from_not_ok_status(e, name)
  File "C:\Users\Rilwa\Anaconda3\lib\site-packages\tensorflow_core\python\framework\ops.py", line 6609, in raise_from_not_ok_status
    six.raise_from(core._status_to_exception(e.code, message), None)
  File "<string>", line 3, in raise_from
tensorflow.python.framework.errors_impl.InvalidArgumentError: Cholesky decomposition was not successful. The input might not be valid. [Op:Cholesky]



Error occured with last batch = 91Number of data per training batch = 10
Traceback (most recent call last):
  File "c:\Users\Rilwa\GoogleDrive\Warwick\PhD\ATI\BNN\layers_and_distributions.py", line 659, in train_loop
    preds = model( feature, tape=tape ) #TODO Debug, remove tape variable from model later
  File "C:\Users\Rilwa\Anaconda3\lib\site-packages\tensorflow_core\python\keras\engine\base_layer.py", line 822, in __call__
    outputs = self.call(cast_inputs, *args, **kwargs)
  File "c:\Users\Rilwa\GoogleDrive\Warwick\PhD\ATI\BNN\layers_and_distributions.py", line 52, in call
    x = self.SRCNN_1(inputs, tape=tape)
  File "C:\Users\Rilwa\Anaconda3\lib\site-packages\tensorflow_core\python\keras\engine\base_layer.py", line 822, in __call__
    outputs = self.call(cast_inputs, *args, **kwargs)
  File "c:\Users\Rilwa\GoogleDrive\Warwick\PhD\ATI\BNN\layers_and_distributions.py", line 110, in call
    self.update_posteriors_dists()
  File "c:\Users\Rilwa\GoogleDrive\Warwick\PhD\ATI\BNN\layers_and_distributions.py", line 211, in update_posteriors_dists
    conv2_betalogtau_post_scale = tf.linalg.cholesky(conv2_tf_U)
  File "C:\Users\Rilwa\Anaconda3\lib\site-packages\tensorflow_core\python\ops\gen_linalg_ops.py", line 712, in cholesky
    _ops.raise_from_not_ok_status(e, name)
  File "C:\Users\Rilwa\Anaconda3\lib\site-packages\tensorflow_core\python\framework\ops.py", line 6609, in raise_from_not_ok_status
    six.raise_from(core._status_to_exception(e.code, message), None)
  File "<string>", line 3, in raise_from
tensorflow.python.framework.errors_impl.InvalidArgumentError: Cholesky decomposition was not successful. The input might not be valid. [Op:Cholesky]



Error occured with last batch = 94Number of data per training batch = 10
Traceback (most recent call last):
  File "c:\Users\Rilwa\GoogleDrive\Warwick\PhD\ATI\BNN\layers_and_distributions.py", line 659, in train_loop
    preds = model( feature, tape=tape ) #TODO Debug, remove tape variable from model later
  File "C:\Users\Rilwa\Anaconda3\lib\site-packages\tensorflow_core\python\keras\engine\base_layer.py", line 822, in __call__
    outputs = self.call(cast_inputs, *args, **kwargs)
  File "c:\Users\Rilwa\GoogleDrive\Warwick\PhD\ATI\BNN\layers_and_distributions.py", line 52, in call
    x = self.SRCNN_1(inputs, tape=tape)
  File "C:\Users\Rilwa\Anaconda3\lib\site-packages\tensorflow_core\python\keras\engine\base_layer.py", line 822, in __call__
    outputs = self.call(cast_inputs, *args, **kwargs)
  File "c:\Users\Rilwa\GoogleDrive\Warwick\PhD\ATI\BNN\layers_and_distributions.py", line 110, in call
    self.update_posteriors_dists()
  File "c:\Users\Rilwa\GoogleDrive\Warwick\PhD\ATI\BNN\layers_and_distributions.py", line 211, in update_posteriors_dists
    conv2_betalogtau_post_scale = tf.linalg.cholesky(conv2_tf_U)
  File "C:\Users\Rilwa\Anaconda3\lib\site-packages\tensorflow_core\python\ops\gen_linalg_ops.py", line 712, in cholesky
    _ops.raise_from_not_ok_status(e, name)
  File "C:\Users\Rilwa\Anaconda3\lib\site-packages\tensorflow_core\python\framework\ops.py", line 6609, in raise_from_not_ok_status
    six.raise_from(core._status_to_exception(e.code, message), None)
  File "<string>", line 3, in raise_from
tensorflow.python.framework.errors_impl.InvalidArgumentError: Cholesky decomposition was not successful. The input might not be valid. [Op:Cholesky]



Error occured with last batch = 97Number of data per training batch = 10
Traceback (most recent call last):
  File "c:\Users\Rilwa\GoogleDrive\Warwick\PhD\ATI\BNN\layers_and_distributions.py", line 659, in train_loop
    preds = model( feature, tape=tape ) #TODO Debug, remove tape variable from model later
  File "C:\Users\Rilwa\Anaconda3\lib\site-packages\tensorflow_core\python\keras\engine\base_layer.py", line 822, in __call__
    outputs = self.call(cast_inputs, *args, **kwargs)
  File "c:\Users\Rilwa\GoogleDrive\Warwick\PhD\ATI\BNN\layers_and_distributions.py", line 52, in call
    x = self.SRCNN_1(inputs, tape=tape)
  File "C:\Users\Rilwa\Anaconda3\lib\site-packages\tensorflow_core\python\keras\engine\base_layer.py", line 822, in __call__
    outputs = self.call(cast_inputs, *args, **kwargs)
  File "c:\Users\Rilwa\GoogleDrive\Warwick\PhD\ATI\BNN\layers_and_distributions.py", line 110, in call
    self.update_posteriors_dists()
  File "c:\Users\Rilwa\GoogleDrive\Warwick\PhD\ATI\BNN\layers_and_distributions.py", line 211, in update_posteriors_dists
    conv2_betalogtau_post_scale = tf.linalg.cholesky(conv2_tf_U)
  File "C:\Users\Rilwa\Anaconda3\lib\site-packages\tensorflow_core\python\ops\gen_linalg_ops.py", line 712, in cholesky
    _ops.raise_from_not_ok_status(e, name)
  File "C:\Users\Rilwa\Anaconda3\lib\site-packages\tensorflow_core\python\framework\ops.py", line 6609, in raise_from_not_ok_status
    six.raise_from(core._status_to_exception(e.code, message), None)
  File "<string>", line 3, in raise_from
tensorflow.python.framework.errors_impl.InvalidArgumentError: Cholesky decomposition was not successful. The input might not be valid. [Op:Cholesky]



Error occured with last batch = 100Number of data per training batch = 10
Traceback (most recent call last):
  File "c:\Users\Rilwa\GoogleDrive\Warwick\PhD\ATI\BNN\layers_and_distributions.py", line 659, in train_loop
    preds = model( feature, tape=tape ) #TODO Debug, remove tape variable from model later
  File "C:\Users\Rilwa\Anaconda3\lib\site-packages\tensorflow_core\python\keras\engine\base_layer.py", line 822, in __call__
    outputs = self.call(cast_inputs, *args, **kwargs)
  File "c:\Users\Rilwa\GoogleDrive\Warwick\PhD\ATI\BNN\layers_and_distributions.py", line 52, in call
    x = self.SRCNN_1(inputs, tape=tape)
  File "C:\Users\Rilwa\Anaconda3\lib\site-packages\tensorflow_core\python\keras\engine\base_layer.py", line 822, in __call__
    outputs = self.call(cast_inputs, *args, **kwargs)
  File "c:\Users\Rilwa\GoogleDrive\Warwick\PhD\ATI\BNN\layers_and_distributions.py", line 110, in call
    self.update_posteriors_dists()
  File "c:\Users\Rilwa\GoogleDrive\Warwick\PhD\ATI\BNN\layers_and_distributions.py", line 211, in update_posteriors_dists
    conv2_betalogtau_post_scale = tf.linalg.cholesky(conv2_tf_U)
  File "C:\Users\Rilwa\Anaconda3\lib\site-packages\tensorflow_core\python\ops\gen_linalg_ops.py", line 712, in cholesky
    _ops.raise_from_not_ok_status(e, name)
  File "C:\Users\Rilwa\Anaconda3\lib\site-packages\tensorflow_core\python\framework\ops.py", line 6609, in raise_from_not_ok_status
    six.raise_from(core._status_to_exception(e.code, message), None)
  File "<string>", line 3, in raise_from
tensorflow.python.framework.errors_impl.InvalidArgumentError: Cholesky decomposition was not successful. The input might not be valid. [Op:Cholesky]



Error occured with last batch = 103Number of data per training batch = 10
Traceback (most recent call last):
  File "c:\Users\Rilwa\GoogleDrive\Warwick\PhD\ATI\BNN\layers_and_distributions.py", line 659, in train_loop
    preds = model( feature, tape=tape ) #TODO Debug, remove tape variable from model later
  File "C:\Users\Rilwa\Anaconda3\lib\site-packages\tensorflow_core\python\keras\engine\base_layer.py", line 822, in __call__
    outputs = self.call(cast_inputs, *args, **kwargs)
  File "c:\Users\Rilwa\GoogleDrive\Warwick\PhD\ATI\BNN\layers_and_distributions.py", line 52, in call
    x = self.SRCNN_1(inputs, tape=tape)
  File "C:\Users\Rilwa\Anaconda3\lib\site-packages\tensorflow_core\python\keras\engine\base_layer.py", line 822, in __call__
    outputs = self.call(cast_inputs, *args, **kwargs)
  File "c:\Users\Rilwa\GoogleDrive\Warwick\PhD\ATI\BNN\layers_and_distributions.py", line 110, in call
    self.update_posteriors_dists()
  File "c:\Users\Rilwa\GoogleDrive\Warwick\PhD\ATI\BNN\layers_and_distributions.py", line 211, in update_posteriors_dists
    conv2_betalogtau_post_scale = tf.linalg.cholesky(conv2_tf_U)
  File "C:\Users\Rilwa\Anaconda3\lib\site-packages\tensorflow_core\python\ops\gen_linalg_ops.py", line 712, in cholesky
    _ops.raise_from_not_ok_status(e, name)
  File "C:\Users\Rilwa\Anaconda3\lib\site-packages\tensorflow_core\python\framework\ops.py", line 6609, in raise_from_not_ok_status
    six.raise_from(core._status_to_exception(e.code, message), None)
  File "<string>", line 3, in raise_from
tensorflow.python.framework.errors_impl.InvalidArgumentError: Cholesky decomposition was not successful. The input might not be valid. [Op:Cholesky]



Error occured with last batch = 106Number of data per training batch = 10
Traceback (most recent call last):
  File "c:\Users\Rilwa\GoogleDrive\Warwick\PhD\ATI\BNN\layers_and_distributions.py", line 659, in train_loop
    preds = model( feature, tape=tape ) #TODO Debug, remove tape variable from model later
  File "C:\Users\Rilwa\Anaconda3\lib\site-packages\tensorflow_core\python\keras\engine\base_layer.py", line 822, in __call__
    outputs = self.call(cast_inputs, *args, **kwargs)
  File "c:\Users\Rilwa\GoogleDrive\Warwick\PhD\ATI\BNN\layers_and_distributions.py", line 52, in call
    x = self.SRCNN_1(inputs, tape=tape)
  File "C:\Users\Rilwa\Anaconda3\lib\site-packages\tensorflow_core\python\keras\engine\base_layer.py", line 822, in __call__
    outputs = self.call(cast_inputs, *args, **kwargs)
  File "c:\Users\Rilwa\GoogleDrive\Warwick\PhD\ATI\BNN\layers_and_distributions.py", line 110, in call
    self.update_posteriors_dists()
  File "c:\Users\Rilwa\GoogleDrive\Warwick\PhD\ATI\BNN\layers_and_distributions.py", line 211, in update_posteriors_dists
    conv2_betalogtau_post_scale = tf.linalg.cholesky(conv2_tf_U)
  File "C:\Users\Rilwa\Anaconda3\lib\site-packages\tensorflow_core\python\ops\gen_linalg_ops.py", line 712, in cholesky
    _ops.raise_from_not_ok_status(e, name)
  File "C:\Users\Rilwa\Anaconda3\lib\site-packages\tensorflow_core\python\framework\ops.py", line 6609, in raise_from_not_ok_status
    six.raise_from(core._status_to_exception(e.code, message), None)
  File "<string>", line 3, in raise_from
tensorflow.python.framework.errors_impl.InvalidArgumentError: Cholesky decomposition was not successful. The input might not be valid. [Op:Cholesky]



Error occured with last batch = 109Number of data per training batch = 10
Traceback (most recent call last):
  File "c:\Users\Rilwa\GoogleDrive\Warwick\PhD\ATI\BNN\layers_and_distributions.py", line 659, in train_loop
    preds = model( feature, tape=tape ) #TODO Debug, remove tape variable from model later
  File "C:\Users\Rilwa\Anaconda3\lib\site-packages\tensorflow_core\python\keras\engine\base_layer.py", line 822, in __call__
    outputs = self.call(cast_inputs, *args, **kwargs)
  File "c:\Users\Rilwa\GoogleDrive\Warwick\PhD\ATI\BNN\layers_and_distributions.py", line 52, in call
    x = self.SRCNN_1(inputs, tape=tape)
  File "C:\Users\Rilwa\Anaconda3\lib\site-packages\tensorflow_core\python\keras\engine\base_layer.py", line 822, in __call__
    outputs = self.call(cast_inputs, *args, **kwargs)
  File "c:\Users\Rilwa\GoogleDrive\Warwick\PhD\ATI\BNN\layers_and_distributions.py", line 110, in call
    self.update_posteriors_dists()
  File "c:\Users\Rilwa\GoogleDrive\Warwick\PhD\ATI\BNN\layers_and_distributions.py", line 211, in update_posteriors_dists
    conv2_betalogtau_post_scale = tf.linalg.cholesky(conv2_tf_U)
  File "C:\Users\Rilwa\Anaconda3\lib\site-packages\tensorflow_core\python\ops\gen_linalg_ops.py", line 712, in cholesky
    _ops.raise_from_not_ok_status(e, name)
  File "C:\Users\Rilwa\Anaconda3\lib\site-packages\tensorflow_core\python\framework\ops.py", line 6609, in raise_from_not_ok_status
    six.raise_from(core._status_to_exception(e.code, message), None)
  File "<string>", line 3, in raise_from
tensorflow.python.framework.errors_impl.InvalidArgumentError: Cholesky decomposition was not successful. The input might not be valid. [Op:Cholesky]



Error occured with last batch = 112Number of data per training batch = 10
Traceback (most recent call last):
  File "c:\Users\Rilwa\GoogleDrive\Warwick\PhD\ATI\BNN\layers_and_distributions.py", line 659, in train_loop
    preds = model( feature, tape=tape ) #TODO Debug, remove tape variable from model later
  File "C:\Users\Rilwa\Anaconda3\lib\site-packages\tensorflow_core\python\keras\engine\base_layer.py", line 822, in __call__
    outputs = self.call(cast_inputs, *args, **kwargs)
  File "c:\Users\Rilwa\GoogleDrive\Warwick\PhD\ATI\BNN\layers_and_distributions.py", line 52, in call
    x = self.SRCNN_1(inputs, tape=tape)
  File "C:\Users\Rilwa\Anaconda3\lib\site-packages\tensorflow_core\python\keras\engine\base_layer.py", line 822, in __call__
    outputs = self.call(cast_inputs, *args, **kwargs)
  File "c:\Users\Rilwa\GoogleDrive\Warwick\PhD\ATI\BNN\layers_and_distributions.py", line 110, in call
    self.update_posteriors_dists()
  File "c:\Users\Rilwa\GoogleDrive\Warwick\PhD\ATI\BNN\layers_and_distributions.py", line 211, in update_posteriors_dists
    conv2_betalogtau_post_scale = tf.linalg.cholesky(conv2_tf_U)
  File "C:\Users\Rilwa\Anaconda3\lib\site-packages\tensorflow_core\python\ops\gen_linalg_ops.py", line 712, in cholesky
    _ops.raise_from_not_ok_status(e, name)
  File "C:\Users\Rilwa\Anaconda3\lib\site-packages\tensorflow_core\python\framework\ops.py", line 6609, in raise_from_not_ok_status
    six.raise_from(core._status_to_exception(e.code, message), None)
  File "<string>", line 3, in raise_from
tensorflow.python.framework.errors_impl.InvalidArgumentError: Cholesky decomposition was not successful. The input might not be valid. [Op:Cholesky]



Error occured with last batch = 115Number of data per training batch = 10
Traceback (most recent call last):
  File "c:\Users\Rilwa\GoogleDrive\Warwick\PhD\ATI\BNN\layers_and_distributions.py", line 659, in train_loop
    preds = model( feature, tape=tape ) #TODO Debug, remove tape variable from model later
  File "C:\Users\Rilwa\Anaconda3\lib\site-packages\tensorflow_core\python\keras\engine\base_layer.py", line 822, in __call__
    outputs = self.call(cast_inputs, *args, **kwargs)
  File "c:\Users\Rilwa\GoogleDrive\Warwick\PhD\ATI\BNN\layers_and_distributions.py", line 52, in call
    x = self.SRCNN_1(inputs, tape=tape)
  File "C:\Users\Rilwa\Anaconda3\lib\site-packages\tensorflow_core\python\keras\engine\base_layer.py", line 822, in __call__
    outputs = self.call(cast_inputs, *args, **kwargs)
  File "c:\Users\Rilwa\GoogleDrive\Warwick\PhD\ATI\BNN\layers_and_distributions.py", line 110, in call
    self.update_posteriors_dists()
  File "c:\Users\Rilwa\GoogleDrive\Warwick\PhD\ATI\BNN\layers_and_distributions.py", line 211, in update_posteriors_dists
    conv2_betalogtau_post_scale = tf.linalg.cholesky(conv2_tf_U)
  File "C:\Users\Rilwa\Anaconda3\lib\site-packages\tensorflow_core\python\ops\gen_linalg_ops.py", line 712, in cholesky
    _ops.raise_from_not_ok_status(e, name)
  File "C:\Users\Rilwa\Anaconda3\lib\site-packages\tensorflow_core\python\framework\ops.py", line 6609, in raise_from_not_ok_status
    six.raise_from(core._status_to_exception(e.code, message), None)
  File "<string>", line 3, in raise_from
tensorflow.python.framework.errors_impl.InvalidArgumentError: Cholesky decomposition was not successful. The input might not be valid. [Op:Cholesky]



Error occured with last batch = 118Number of data per training batch = 10
Traceback (most recent call last):
  File "c:\Users\Rilwa\GoogleDrive\Warwick\PhD\ATI\BNN\layers_and_distributions.py", line 659, in train_loop
    preds = model( feature, tape=tape ) #TODO Debug, remove tape variable from model later
  File "C:\Users\Rilwa\Anaconda3\lib\site-packages\tensorflow_core\python\keras\engine\base_layer.py", line 822, in __call__
    outputs = self.call(cast_inputs, *args, **kwargs)
  File "c:\Users\Rilwa\GoogleDrive\Warwick\PhD\ATI\BNN\layers_and_distributions.py", line 52, in call
    x = self.SRCNN_1(inputs, tape=tape)
  File "C:\Users\Rilwa\Anaconda3\lib\site-packages\tensorflow_core\python\keras\engine\base_layer.py", line 822, in __call__
    outputs = self.call(cast_inputs, *args, **kwargs)
  File "c:\Users\Rilwa\GoogleDrive\Warwick\PhD\ATI\BNN\layers_and_distributions.py", line 110, in call
    self.update_posteriors_dists()
  File "c:\Users\Rilwa\GoogleDrive\Warwick\PhD\ATI\BNN\layers_and_distributions.py", line 211, in update_posteriors_dists
    conv2_betalogtau_post_scale = tf.linalg.cholesky(conv2_tf_U)
  File "C:\Users\Rilwa\Anaconda3\lib\site-packages\tensorflow_core\python\ops\gen_linalg_ops.py", line 712, in cholesky
    _ops.raise_from_not_ok_status(e, name)
  File "C:\Users\Rilwa\Anaconda3\lib\site-packages\tensorflow_core\python\framework\ops.py", line 6609, in raise_from_not_ok_status
    six.raise_from(core._status_to_exception(e.code, message), None)
  File "<string>", line 3, in raise_from
tensorflow.python.framework.errors_impl.InvalidArgumentError: Cholesky decomposition was not successful. The input might not be valid. [Op:Cholesky]



Error occured with last batch = 121Number of data per training batch = 10
Traceback (most recent call last):
  File "c:\Users\Rilwa\GoogleDrive\Warwick\PhD\ATI\BNN\layers_and_distributions.py", line 659, in train_loop
    preds = model( feature, tape=tape ) #TODO Debug, remove tape variable from model later
  File "C:\Users\Rilwa\Anaconda3\lib\site-packages\tensorflow_core\python\keras\engine\base_layer.py", line 822, in __call__
    outputs = self.call(cast_inputs, *args, **kwargs)
  File "c:\Users\Rilwa\GoogleDrive\Warwick\PhD\ATI\BNN\layers_and_distributions.py", line 52, in call
    x = self.SRCNN_1(inputs, tape=tape)
  File "C:\Users\Rilwa\Anaconda3\lib\site-packages\tensorflow_core\python\keras\engine\base_layer.py", line 822, in __call__
    outputs = self.call(cast_inputs, *args, **kwargs)
  File "c:\Users\Rilwa\GoogleDrive\Warwick\PhD\ATI\BNN\layers_and_distributions.py", line 110, in call
    self.update_posteriors_dists()
  File "c:\Users\Rilwa\GoogleDrive\Warwick\PhD\ATI\BNN\layers_and_distributions.py", line 211, in update_posteriors_dists
    conv2_betalogtau_post_scale = tf.linalg.cholesky(conv2_tf_U)
  File "C:\Users\Rilwa\Anaconda3\lib\site-packages\tensorflow_core\python\ops\gen_linalg_ops.py", line 712, in cholesky
    _ops.raise_from_not_ok_status(e, name)
  File "C:\Users\Rilwa\Anaconda3\lib\site-packages\tensorflow_core\python\framework\ops.py", line 6609, in raise_from_not_ok_status
    six.raise_from(core._status_to_exception(e.code, message), None)
  File "<string>", line 3, in raise_from
tensorflow.python.framework.errors_impl.InvalidArgumentError: Cholesky decomposition was not successful. The input might not be valid. [Op:Cholesky]



Error occured with last batch = 124Number of data per training batch = 10
Traceback (most recent call last):
  File "c:\Users\Rilwa\GoogleDrive\Warwick\PhD\ATI\BNN\layers_and_distributions.py", line 659, in train_loop
    preds = model( feature, tape=tape ) #TODO Debug, remove tape variable from model later
  File "C:\Users\Rilwa\Anaconda3\lib\site-packages\tensorflow_core\python\keras\engine\base_layer.py", line 822, in __call__
    outputs = self.call(cast_inputs, *args, **kwargs)
  File "c:\Users\Rilwa\GoogleDrive\Warwick\PhD\ATI\BNN\layers_and_distributions.py", line 52, in call
    x = self.SRCNN_1(inputs, tape=tape)
  File "C:\Users\Rilwa\Anaconda3\lib\site-packages\tensorflow_core\python\keras\engine\base_layer.py", line 822, in __call__
    outputs = self.call(cast_inputs, *args, **kwargs)
  File "c:\Users\Rilwa\GoogleDrive\Warwick\PhD\ATI\BNN\layers_and_distributions.py", line 110, in call
    self.update_posteriors_dists()
  File "c:\Users\Rilwa\GoogleDrive\Warwick\PhD\ATI\BNN\layers_and_distributions.py", line 211, in update_posteriors_dists
    conv2_betalogtau_post_scale = tf.linalg.cholesky(conv2_tf_U)
  File "C:\Users\Rilwa\Anaconda3\lib\site-packages\tensorflow_core\python\ops\gen_linalg_ops.py", line 712, in cholesky
    _ops.raise_from_not_ok_status(e, name)
  File "C:\Users\Rilwa\Anaconda3\lib\site-packages\tensorflow_core\python\framework\ops.py", line 6609, in raise_from_not_ok_status
    six.raise_from(core._status_to_exception(e.code, message), None)
  File "<string>", line 3, in raise_from
tensorflow.python.framework.errors_impl.InvalidArgumentError: Cholesky decomposition was not successful. The input might not be valid. [Op:Cholesky]



Error occured with last batch = 127Number of data per training batch = 10
Traceback (most recent call last):
  File "c:\Users\Rilwa\GoogleDrive\Warwick\PhD\ATI\BNN\layers_and_distributions.py", line 659, in train_loop
    preds = model( feature, tape=tape ) #TODO Debug, remove tape variable from model later
  File "C:\Users\Rilwa\Anaconda3\lib\site-packages\tensorflow_core\python\keras\engine\base_layer.py", line 822, in __call__
    outputs = self.call(cast_inputs, *args, **kwargs)
  File "c:\Users\Rilwa\GoogleDrive\Warwick\PhD\ATI\BNN\layers_and_distributions.py", line 52, in call
    x = self.SRCNN_1(inputs, tape=tape)
  File "C:\Users\Rilwa\Anaconda3\lib\site-packages\tensorflow_core\python\keras\engine\base_layer.py", line 822, in __call__
    outputs = self.call(cast_inputs, *args, **kwargs)
  File "c:\Users\Rilwa\GoogleDrive\Warwick\PhD\ATI\BNN\layers_and_distributions.py", line 110, in call
    self.update_posteriors_dists()
  File "c:\Users\Rilwa\GoogleDrive\Warwick\PhD\ATI\BNN\layers_and_distributions.py", line 211, in update_posteriors_dists
    conv2_betalogtau_post_scale = tf.linalg.cholesky(conv2_tf_U)
  File "C:\Users\Rilwa\Anaconda3\lib\site-packages\tensorflow_core\python\ops\gen_linalg_ops.py", line 712, in cholesky
    _ops.raise_from_not_ok_status(e, name)
  File "C:\Users\Rilwa\Anaconda3\lib\site-packages\tensorflow_core\python\framework\ops.py", line 6609, in raise_from_not_ok_status
    six.raise_from(core._status_to_exception(e.code, message), None)
  File "<string>", line 3, in raise_from
tensorflow.python.framework.errors_impl.InvalidArgumentError: Cholesky decomposition was not successful. The input might not be valid. [Op:Cholesky]



Error occured with last batch = 130Number of data per training batch = 10
Traceback (most recent call last):
  File "c:\Users\Rilwa\GoogleDrive\Warwick\PhD\ATI\BNN\layers_and_distributions.py", line 659, in train_loop
    preds = model( feature, tape=tape ) #TODO Debug, remove tape variable from model later
  File "C:\Users\Rilwa\Anaconda3\lib\site-packages\tensorflow_core\python\keras\engine\base_layer.py", line 822, in __call__
    outputs = self.call(cast_inputs, *args, **kwargs)
  File "c:\Users\Rilwa\GoogleDrive\Warwick\PhD\ATI\BNN\layers_and_distributions.py", line 52, in call
    x = self.SRCNN_1(inputs, tape=tape)
  File "C:\Users\Rilwa\Anaconda3\lib\site-packages\tensorflow_core\python\keras\engine\base_layer.py", line 822, in __call__
    outputs = self.call(cast_inputs, *args, **kwargs)
  File "c:\Users\Rilwa\GoogleDrive\Warwick\PhD\ATI\BNN\layers_and_distributions.py", line 110, in call
    self.update_posteriors_dists()
  File "c:\Users\Rilwa\GoogleDrive\Warwick\PhD\ATI\BNN\layers_and_distributions.py", line 211, in update_posteriors_dists
    conv2_betalogtau_post_scale = tf.linalg.cholesky(conv2_tf_U)
  File "C:\Users\Rilwa\Anaconda3\lib\site-packages\tensorflow_core\python\ops\gen_linalg_ops.py", line 712, in cholesky
    _ops.raise_from_not_ok_status(e, name)
  File "C:\Users\Rilwa\Anaconda3\lib\site-packages\tensorflow_core\python\framework\ops.py", line 6609, in raise_from_not_ok_status
    six.raise_from(core._status_to_exception(e.code, message), None)
  File "<string>", line 3, in raise_from
tensorflow.python.framework.errors_impl.InvalidArgumentError: Cholesky decomposition was not successful. The input might not be valid. [Op:Cholesky]



Error occured with last batch = 133Number of data per training batch = 10
Traceback (most recent call last):
  File "c:\Users\Rilwa\GoogleDrive\Warwick\PhD\ATI\BNN\layers_and_distributions.py", line 659, in train_loop
    preds = model( feature, tape=tape ) #TODO Debug, remove tape variable from model later
  File "C:\Users\Rilwa\Anaconda3\lib\site-packages\tensorflow_core\python\keras\engine\base_layer.py", line 822, in __call__
    outputs = self.call(cast_inputs, *args, **kwargs)
  File "c:\Users\Rilwa\GoogleDrive\Warwick\PhD\ATI\BNN\layers_and_distributions.py", line 52, in call
    x = self.SRCNN_1(inputs, tape=tape)
  File "C:\Users\Rilwa\Anaconda3\lib\site-packages\tensorflow_core\python\keras\engine\base_layer.py", line 822, in __call__
    outputs = self.call(cast_inputs, *args, **kwargs)
  File "c:\Users\Rilwa\GoogleDrive\Warwick\PhD\ATI\BNN\layers_and_distributions.py", line 110, in call
    self.update_posteriors_dists()
  File "c:\Users\Rilwa\GoogleDrive\Warwick\PhD\ATI\BNN\layers_and_distributions.py", line 211, in update_posteriors_dists
    conv2_betalogtau_post_scale = tf.linalg.cholesky(conv2_tf_U)
  File "C:\Users\Rilwa\Anaconda3\lib\site-packages\tensorflow_core\python\ops\gen_linalg_ops.py", line 712, in cholesky
    _ops.raise_from_not_ok_status(e, name)
  File "C:\Users\Rilwa\Anaconda3\lib\site-packages\tensorflow_core\python\framework\ops.py", line 6609, in raise_from_not_ok_status
    six.raise_from(core._status_to_exception(e.code, message), None)
  File "<string>", line 3, in raise_from
tensorflow.python.framework.errors_impl.InvalidArgumentError: Cholesky decomposition was not successful. The input might not be valid. [Op:Cholesky]



Error occured with last batch = 136Number of data per training batch = 10
Traceback (most recent call last):
  File "c:\Users\Rilwa\GoogleDrive\Warwick\PhD\ATI\BNN\layers_and_distributions.py", line 659, in train_loop
    preds = model( feature, tape=tape ) #TODO Debug, remove tape variable from model later
  File "C:\Users\Rilwa\Anaconda3\lib\site-packages\tensorflow_core\python\keras\engine\base_layer.py", line 822, in __call__
    outputs = self.call(cast_inputs, *args, **kwargs)
  File "c:\Users\Rilwa\GoogleDrive\Warwick\PhD\ATI\BNN\layers_and_distributions.py", line 52, in call
    x = self.SRCNN_1(inputs, tape=tape)
  File "C:\Users\Rilwa\Anaconda3\lib\site-packages\tensorflow_core\python\keras\engine\base_layer.py", line 822, in __call__
    outputs = self.call(cast_inputs, *args, **kwargs)
  File "c:\Users\Rilwa\GoogleDrive\Warwick\PhD\ATI\BNN\layers_and_distributions.py", line 110, in call
    self.update_posteriors_dists()
  File "c:\Users\Rilwa\GoogleDrive\Warwick\PhD\ATI\BNN\layers_and_distributions.py", line 211, in update_posteriors_dists
    conv2_betalogtau_post_scale = tf.linalg.cholesky(conv2_tf_U)
  File "C:\Users\Rilwa\Anaconda3\lib\site-packages\tensorflow_core\python\ops\gen_linalg_ops.py", line 712, in cholesky
    _ops.raise_from_not_ok_status(e, name)
  File "C:\Users\Rilwa\Anaconda3\lib\site-packages\tensorflow_core\python\framework\ops.py", line 6609, in raise_from_not_ok_status
    six.raise_from(core._status_to_exception(e.code, message), None)
  File "<string>", line 3, in raise_from
tensorflow.python.framework.errors_impl.InvalidArgumentError: Cholesky decomposition was not successful. The input might not be valid. [Op:Cholesky]



Error occured with last batch = 139Number of data per training batch = 10
Traceback (most recent call last):
  File "c:\Users\Rilwa\GoogleDrive\Warwick\PhD\ATI\BNN\layers_and_distributions.py", line 659, in train_loop
    preds = model( feature, tape=tape ) #TODO Debug, remove tape variable from model later
  File "C:\Users\Rilwa\Anaconda3\lib\site-packages\tensorflow_core\python\keras\engine\base_layer.py", line 822, in __call__
    outputs = self.call(cast_inputs, *args, **kwargs)
  File "c:\Users\Rilwa\GoogleDrive\Warwick\PhD\ATI\BNN\layers_and_distributions.py", line 52, in call
    x = self.SRCNN_1(inputs, tape=tape)
  File "C:\Users\Rilwa\Anaconda3\lib\site-packages\tensorflow_core\python\keras\engine\base_layer.py", line 822, in __call__
    outputs = self.call(cast_inputs, *args, **kwargs)
  File "c:\Users\Rilwa\GoogleDrive\Warwick\PhD\ATI\BNN\layers_and_distributions.py", line 110, in call
    self.update_posteriors_dists()
  File "c:\Users\Rilwa\GoogleDrive\Warwick\PhD\ATI\BNN\layers_and_distributions.py", line 211, in update_posteriors_dists
    conv2_betalogtau_post_scale = tf.linalg.cholesky(conv2_tf_U)
  File "C:\Users\Rilwa\Anaconda3\lib\site-packages\tensorflow_core\python\ops\gen_linalg_ops.py", line 712, in cholesky
    _ops.raise_from_not_ok_status(e, name)
  File "C:\Users\Rilwa\Anaconda3\lib\site-packages\tensorflow_core\python\framework\ops.py", line 6609, in raise_from_not_ok_status
    six.raise_from(core._status_to_exception(e.code, message), None)
  File "<string>", line 3, in raise_from
tensorflow.python.framework.errors_impl.InvalidArgumentError: Cholesky decomposition was not successful. The input might not be valid. [Op:Cholesky]



Error occured with last batch = 142Number of data per training batch = 10
Traceback (most recent call last):
  File "c:\Users\Rilwa\GoogleDrive\Warwick\PhD\ATI\BNN\layers_and_distributions.py", line 659, in train_loop
    preds = model( feature, tape=tape ) #TODO Debug, remove tape variable from model later
  File "C:\Users\Rilwa\Anaconda3\lib\site-packages\tensorflow_core\python\keras\engine\base_layer.py", line 822, in __call__
    outputs = self.call(cast_inputs, *args, **kwargs)
  File "c:\Users\Rilwa\GoogleDrive\Warwick\PhD\ATI\BNN\layers_and_distributions.py", line 52, in call
    x = self.SRCNN_1(inputs, tape=tape)
  File "C:\Users\Rilwa\Anaconda3\lib\site-packages\tensorflow_core\python\keras\engine\base_layer.py", line 822, in __call__
    outputs = self.call(cast_inputs, *args, **kwargs)
  File "c:\Users\Rilwa\GoogleDrive\Warwick\PhD\ATI\BNN\layers_and_distributions.py", line 110, in call
    self.update_posteriors_dists()
  File "c:\Users\Rilwa\GoogleDrive\Warwick\PhD\ATI\BNN\layers_and_distributions.py", line 211, in update_posteriors_dists
    conv2_betalogtau_post_scale = tf.linalg.cholesky(conv2_tf_U)
  File "C:\Users\Rilwa\Anaconda3\lib\site-packages\tensorflow_core\python\ops\gen_linalg_ops.py", line 712, in cholesky
    _ops.raise_from_not_ok_status(e, name)
  File "C:\Users\Rilwa\Anaconda3\lib\site-packages\tensorflow_core\python\framework\ops.py", line 6609, in raise_from_not_ok_status
    six.raise_from(core._status_to_exception(e.code, message), None)
  File "<string>", line 3, in raise_from
tensorflow.python.framework.errors_impl.InvalidArgumentError: Cholesky decomposition was not successful. The input might not be valid. [Op:Cholesky]



Error occured with last batch = 145Number of data per training batch = 10
Traceback (most recent call last):
  File "c:\Users\Rilwa\GoogleDrive\Warwick\PhD\ATI\BNN\layers_and_distributions.py", line 659, in train_loop
    preds = model( feature, tape=tape ) #TODO Debug, remove tape variable from model later
  File "C:\Users\Rilwa\Anaconda3\lib\site-packages\tensorflow_core\python\keras\engine\base_layer.py", line 822, in __call__
    outputs = self.call(cast_inputs, *args, **kwargs)
  File "c:\Users\Rilwa\GoogleDrive\Warwick\PhD\ATI\BNN\layers_and_distributions.py", line 52, in call
    x = self.SRCNN_1(inputs, tape=tape)
  File "C:\Users\Rilwa\Anaconda3\lib\site-packages\tensorflow_core\python\keras\engine\base_layer.py", line 822, in __call__
    outputs = self.call(cast_inputs, *args, **kwargs)
  File "c:\Users\Rilwa\GoogleDrive\Warwick\PhD\ATI\BNN\layers_and_distributions.py", line 110, in call
    self.update_posteriors_dists()
  File "c:\Users\Rilwa\GoogleDrive\Warwick\PhD\ATI\BNN\layers_and_distributions.py", line 211, in update_posteriors_dists
    conv2_betalogtau_post_scale = tf.linalg.cholesky(conv2_tf_U)
  File "C:\Users\Rilwa\Anaconda3\lib\site-packages\tensorflow_core\python\ops\gen_linalg_ops.py", line 712, in cholesky
    _ops.raise_from_not_ok_status(e, name)
  File "C:\Users\Rilwa\Anaconda3\lib\site-packages\tensorflow_core\python\framework\ops.py", line 6609, in raise_from_not_ok_status
    six.raise_from(core._status_to_exception(e.code, message), None)
  File "<string>", line 3, in raise_from
tensorflow.python.framework.errors_impl.InvalidArgumentError: Cholesky decomposition was not successful. The input might not be valid. [Op:Cholesky]



Error occured with last batch = 148Number of data per training batch = 10
Traceback (most recent call last):
  File "c:\Users\Rilwa\GoogleDrive\Warwick\PhD\ATI\BNN\layers_and_distributions.py", line 659, in train_loop
    preds = model( feature, tape=tape ) #TODO Debug, remove tape variable from model later
  File "C:\Users\Rilwa\Anaconda3\lib\site-packages\tensorflow_core\python\keras\engine\base_layer.py", line 822, in __call__
    outputs = self.call(cast_inputs, *args, **kwargs)
  File "c:\Users\Rilwa\GoogleDrive\Warwick\PhD\ATI\BNN\layers_and_distributions.py", line 52, in call
    x = self.SRCNN_1(inputs, tape=tape)
  File "C:\Users\Rilwa\Anaconda3\lib\site-packages\tensorflow_core\python\keras\engine\base_layer.py", line 822, in __call__
    outputs = self.call(cast_inputs, *args, **kwargs)
  File "c:\Users\Rilwa\GoogleDrive\Warwick\PhD\ATI\BNN\layers_and_distributions.py", line 110, in call
    self.update_posteriors_dists()
  File "c:\Users\Rilwa\GoogleDrive\Warwick\PhD\ATI\BNN\layers_and_distributions.py", line 211, in update_posteriors_dists
    conv2_betalogtau_post_scale = tf.linalg.cholesky(conv2_tf_U)
  File "C:\Users\Rilwa\Anaconda3\lib\site-packages\tensorflow_core\python\ops\gen_linalg_ops.py", line 712, in cholesky
    _ops.raise_from_not_ok_status(e, name)
  File "C:\Users\Rilwa\Anaconda3\lib\site-packages\tensorflow_core\python\framework\ops.py", line 6609, in raise_from_not_ok_status
    six.raise_from(core._status_to_exception(e.code, message), None)
  File "<string>", line 3, in raise_from
tensorflow.python.framework.errors_impl.InvalidArgumentError: Cholesky decomposition was not successful. The input might not be valid. [Op:Cholesky]



Error occured with last batch = 151Number of data per training batch = 10
Traceback (most recent call last):
  File "c:\Users\Rilwa\GoogleDrive\Warwick\PhD\ATI\BNN\layers_and_distributions.py", line 659, in train_loop
    preds = model( feature, tape=tape ) #TODO Debug, remove tape variable from model later
  File "C:\Users\Rilwa\Anaconda3\lib\site-packages\tensorflow_core\python\keras\engine\base_layer.py", line 822, in __call__
    outputs = self.call(cast_inputs, *args, **kwargs)
  File "c:\Users\Rilwa\GoogleDrive\Warwick\PhD\ATI\BNN\layers_and_distributions.py", line 52, in call
    x = self.SRCNN_1(inputs, tape=tape)
  File "C:\Users\Rilwa\Anaconda3\lib\site-packages\tensorflow_core\python\keras\engine\base_layer.py", line 822, in __call__
    outputs = self.call(cast_inputs, *args, **kwargs)
  File "c:\Users\Rilwa\GoogleDrive\Warwick\PhD\ATI\BNN\layers_and_distributions.py", line 110, in call
    self.update_posteriors_dists()
  File "c:\Users\Rilwa\GoogleDrive\Warwick\PhD\ATI\BNN\layers_and_distributions.py", line 211, in update_posteriors_dists
    conv2_betalogtau_post_scale = tf.linalg.cholesky(conv2_tf_U)
  File "C:\Users\Rilwa\Anaconda3\lib\site-packages\tensorflow_core\python\ops\gen_linalg_ops.py", line 712, in cholesky
    _ops.raise_from_not_ok_status(e, name)
  File "C:\Users\Rilwa\Anaconda3\lib\site-packages\tensorflow_core\python\framework\ops.py", line 6609, in raise_from_not_ok_status
    six.raise_from(core._status_to_exception(e.code, message), None)
  File "<string>", line 3, in raise_from
tensorflow.python.framework.errors_impl.InvalidArgumentError: Cholesky decomposition was not successful. The input might not be valid. [Op:Cholesky]



Error occured with last batch = 19Number of data per training batch = 10
Traceback (most recent call last):
  File "c:\Users\Rilwa\GoogleDrive\Warwick\PhD\ATI\BNN\layers_and_distributions.py", line 659, in train_loop
    preds = model( feature, tape=tape ) #TODO Debug, remove tape variable from model later
  File "C:\Users\Rilwa\Anaconda3\lib\site-packages\tensorflow_core\python\keras\engine\base_layer.py", line 822, in __call__
    outputs = self.call(cast_inputs, *args, **kwargs)
  File "c:\Users\Rilwa\GoogleDrive\Warwick\PhD\ATI\BNN\layers_and_distributions.py", line 52, in call
    x = self.SRCNN_1(inputs, tape=tape)
  File "C:\Users\Rilwa\Anaconda3\lib\site-packages\tensorflow_core\python\keras\engine\base_layer.py", line 822, in __call__
    outputs = self.call(cast_inputs, *args, **kwargs)
  File "c:\Users\Rilwa\GoogleDrive\Warwick\PhD\ATI\BNN\layers_and_distributions.py", line 110, in call
    self.update_posteriors_dists()
  File "c:\Users\Rilwa\GoogleDrive\Warwick\PhD\ATI\BNN\layers_and_distributions.py", line 211, in update_posteriors_dists
    conv2_betalogtau_post_scale = tf.linalg.cholesky(conv2_tf_U)
  File "C:\Users\Rilwa\Anaconda3\lib\site-packages\tensorflow_core\python\ops\gen_linalg_ops.py", line 712, in cholesky
    _ops.raise_from_not_ok_status(e, name)
  File "C:\Users\Rilwa\Anaconda3\lib\site-packages\tensorflow_core\python\framework\ops.py", line 6609, in raise_from_not_ok_status
    six.raise_from(core._status_to_exception(e.code, message), None)
  File "<string>", line 3, in raise_from
tensorflow.python.framework.errors_impl.InvalidArgumentError: Cholesky decomposition was not successful. The input might not be valid. [Op:Cholesky]
